Workbook

Sheet Read Me
B2: Master Inventory Dashboard — April 2026
B3: Diamond Furniture — consolidated from Production_update_APRIL_2026.xlsx
B5: What this is
B6: Your production file already tracks opening stock, machine-wise production, sales by dealer, and closing stock —
B7: in real detail, across 27 separate product tabs. That level of detail is genuinely good. The gap was visibility:
B8: nothing pulled it together, so spotting what's low, overstocked, or wrong meant checking all 27 tabs by hand.
B9: This workbook pulls every SKU (706 of them — product x colour) into one place, with automatic flags.
B11: What's in each tab
B12: ALERTS — the two things worth looking at first: SKUs with negative stock (a data/recording issue, not a real
B13: negative quantity), and SKUs that look critically low relative to this month's sales.
B14: MASTER SKU LIST — all 706 SKUs: opening stock, sold this period, closing stock, and a status flag for each.
B15: CATEGORY SUMMARY — totals rolled up by product line, so you can see which lines are moving and which aren't
... B29: they'll be based on an actual average instead of a single month.

Sheet Alerts
B2: Alerts — Where to Look First
B3: Pulled automatically from Master SKU List. Refresh with Ctrl+Alt+F9 if numbers look stale.
B5: Negative Stock (data issue) | D5: Low Stock (urgent) | F5: Overstock | H5: No Activity This Month
B6: =COUNTIF('Master SKU List'!H3:H698,"Negative (check entry)") -> 28 | D6: =COUNTIF('Master SKU List'!H3:H698,"Low Stock") -> 50 | F6: =COUNTIF('Master SKU List'!H3:H698,"Overstock") -> 76 | H6: =COUNTIF('Master SKU List'!H3:H698,"No Activity") -> 363
B9: Negative Stock — check these entries first
B10: Product Sheet | C10: Model / Variant | D10: Colour | E10: Closing Stock | F10: Sold This Period
B11: F.Stand & C Table | C11: Fridge Stand 3 | D11: Brown | E11: -1600 | F11: 1600
B12: BIG CHAIR | C12: 6002 (Chattai) | D12: B.Gold | E12: -800 | F12: 800
B13: F.Stand & C Table | C13: Fridge Stand 3 | D13: Black | E13: -580 | F13: 580
B14: F.Stand & C Table | C14: Fridge Stand 3 | D14: Cherry | E14: -520 | F14: 520
B15: Aless | C15: 102(Gold-P) | D15: Brown | E15: -500 | F15: 1800
B16: BIG CHAIR | C16: 10001 New (Goli) | D16: Mix | E16: -448 | F16: 16176
B17: Small Chair | C17: 403(WIFI) | D17: S.Wood | E17: -280 | F17: 2500
B18: Aless | C18: 101(Chattai) | D18: Orange | E18: -220 | F18: 2240
B19: BIG CHAIR | C19: 6002 (Chattai) | D19: Black | E19: -192 | F19: 192
B20: BIG CHAIR | C20: 5003 (Flower) | D20: S.Wood | E20: -176 | F20: 2016
B21: Tea Table | C21: Tea Table | D21: Brown | E21: -168 | F21: 2016
B22: F.Stand & C Table | C22: Fridge Stand 1 | D22: Red First | E22: -160 | F22: 160
... B31: EV Chair | C31: 201 | D31: Red First | E31: -32 | F31: 32
B32: Jordan Chair | D32: G.Black | E32: -24 | F32: 24
B33: Small Chair | C33: 402(Chattai) | D33: A.Gold | E33: -20 | F33: 3520
B34: High cros | C34: 601 (High Cros) | D34: Yellow | E34: -20 | F34: 40
B35: F.Stand & C Table | C35: Fridge Stand 1 | D35: P.Green | E35: -20 | F35: 20
B36: EV Chair | C36: 201 | D36: P.Blue | E36: -16 | F36: 16
B37: Garden Table | C37: Garden Table | D37: Red First | E37: -12 | F37: 12
B38: Garden Table | C38: Garden Table | D38: T.Wood/M.B | E38: -12 | F38: 528
B41: Low Stock — under 2 weeks of cover at this month's sell-through rate
B42: Product Sheet | C42: Model / Variant | D42: Colour | E42: Closing Stock | F42: Months of Cover
B43: BIG CHAIR | C43: 2001(New) | D43: S-W | E43: 0 | F43: 0
B44: BIG CHAIR | C44: 5003 (Flower) | D44: R-W | E44: 0 | F44: 0
B45: BIG CHAIR | C45: 6003 (Patti) | D45: R-W | E45: 0 | F45: 0
B46: Garden Table | C46: Garden Table | D46: Silver.B | E46: 0 | F46: 0
B47: Garden Table | C47: Garden Table | D47: R-W | E47: 0 | F47: 0
B48: Activa | C48: 4003 (Goli) | D48: M.BZ | E48: 0 | F48: 0
B49: Small Chair | C49: 403(WIFI) | D49: P.Pink | E49: 0 | F49: 0
B50: EV Chair | C50: 202 | D50: Brown | E50: 0 | F50: 0
B51: Yoddha | C51: 502 | D51: S.Black | E51: 0 | F51: 0
B52: Jordan New | C52: 1003 | D52: S.Black | E52: 0 | F52: 0
B53: ARM LESS SUMO | C53: ARM LESS SUMO | D53: S. BLACK SECOND | E53: 0 | F53: 0
B54: Dining Table | C54: Dining - Top Square | D54: S.Black | E54: 0 | F54: 0
...

Sheet Master SKU List
A1: All SKUs consolidated from the 27 product tabs in Production_update_APRIL_2026.xlsx. Source figures (blue) are pulled as-is; flags (black) are calculated.
A2: Product Sheet | B2: Model / Variant | C2: Colour | D2: Opening Stock | E2: Sold This Period | F2: Closing Stock | G2: Months of Cover | H2: Status | I2: Notes
A3: BIG CHAIR | B3: 2001(New) | C3: S-W | D3: 976 | E3: 976 | F3: 0 | G3: =IF(OR(E3="",E3=0),"n/a",IF(F3<0,"n/a",ROUND(F3/E3,1))) -> 0 | H3: =IF(F3<0,"Negative (check entry)",IF(OR(E3="",E3=0),IF(F3=0,"No Activity","OK"),IF(F3/E3<0.5,"Low Stock",IF(F3/E3>3,"Overstock","OK")))) -> Low Stock
A4: BIG CHAIR | B4: 2001(New) | C4: G.B | D4: 0 | E4: 0 | F4: 0 | G4: =IF(OR(E4="",E4=0),"n/a",IF(F4<0,"n/a",ROUND(F4/E4,1))) -> n/a | H4: =IF(F4<0,"Negative (check entry)",IF(OR(E4="",E4=0),IF(F4=0,"No Activity","OK"),IF(F4/E4<0.5,"Low Stock",IF(F4/E4>3,"Overstock","OK")))) -> No Activity
A5: BIG CHAIR | B5: 2001(New) | C5: B.Silver | D5: 1264 | E5: 32 | F5: 1232 | G5: =IF(OR(E5="",E5=0),"n/a",IF(F5<0,"n/a",ROUND(F5/E5,1))) -> 38.5 | H5: =IF(F5<0,"Negative (check entry)",IF(OR(E5="",E5=0),IF(F5=0,"No Activity","OK"),IF(F5/E5<0.5,"Low Stock",IF(F5/E5>3,"Overstock","OK")))) -> Overstock
A6: BIG CHAIR | B6: 2001(New) | C6: A.Gold | D6: 0 | E6: 0 | F6: 0 | G6: =IF(OR(E6="",E6=0),"n/a",IF(F6<0,"n/a",ROUND(F6/E6,1))) -> n/a | H6: =IF(F6<0,"Negative (check entry)",IF(OR(E6="",E6=0),IF(F6=0,"No Activity","OK"),IF(F6/E6<0.5,"Low Stock",IF(F6/E6>3,"Overstock","OK")))) -> No Activity
A7: BIG CHAIR | B7: 2001(New) | C7: M.Bz | D7: 768 | E7: 0 | F7: 768 | G7: =IF(OR(E7="",E7=0),"n/a",IF(F7<0,"n/a",ROUND(F7/E7,1))) -> n/a | H7: =IF(F7<0,"Negative (check entry)",IF(OR(E7="",E7=0),IF(F7=0,"No Activity","OK"),IF(F7/E7<0.5,"Low Stock",IF(F7/E7>3,"Overstock","OK")))) -> OK
A8: BIG CHAIR | B8: 2001(New) | C8: P.Silver | D8: 0 | E8: 0 | F8: 0 | G8: =IF(OR(E8="",E8=0),"n/a",IF(F8<0,"n/a",ROUND(F8/E8,1))) -> n/a | H8: =IF(F8<0,"Negative (check entry)",IF(OR(E8="",E8=0),IF(F8=0,"No Activity","OK"),IF(F8/E8<0.5,"Low Stock",IF(F8/E8>3,"Overstock","OK")))) -> No Activity
A9: BIG CHAIR | B9: 2001(New) | C9: R-W | D9: 912 | E9: 496 | F9: 416 | G9: =IF(OR(E9="",E9=0),"n/a",IF(F9<0,"n/a",ROUND(F9/E9,1))) -> 0.8 | H9: =IF(F9<0,"Negative (check entry)",IF(OR(E9="",E9=0),IF(F9=0,"No Activity","OK"),IF(F9/E9<0.5,"Low Stock",IF(F9/E9>3,"Overstock","OK")))) -> OK
A10: BIG CHAIR | B10: 2001(New) | C10: Brown | D10: 0 | E10: 0 | F10: 0 | G10: =IF(OR(E10="",E10=0),"n/a",IF(F10<0,"n/a",ROUND(F10/E10,1))) -> n/a | H10: =IF(F10<0,"Negative (check entry)",IF(OR(E10="",E10=0),IF(F10=0,"No Activity","OK"),IF(F10/E10<0.5,"Low Stock",IF(F10/E10>3,"Overstock","OK")))) -> No Activity
A11: BIG CHAIR | B11: 5001 (Maharaja) | C11: S-W | D11: 0 | E11: 0 | F11: 0 | G11: =IF(OR(E11="",E11=0),"n/a",IF(F11<0,"n/a",ROUND(F11/E11,1))) -> n/a | H11: =IF(F11<0,"Negative (check entry)",IF(OR(E11="",E11=0),IF(F11=0,"No Activity","OK"),IF(F11/E11<0.5,"Low Stock",IF(F11/E11>3,"Overstock","OK")))) -> No Activity
A12: BIG CHAIR | B12: 5001 (Maharaja) | C12: C-W | D12: 0 | E12: 0 | F12: 0 | G12: =IF(OR(E12="",E12=0),"n/a",IF(F12<0,"n/a",ROUND(F12/E12,1))) -> n/a | H12: =IF(F12<0,"Negative (check entry)",IF(OR(E12="",E12=0),IF(F12=0,"No Activity","OK"),IF(F12/E12<0.5,"Low Stock",IF(F12/E12>3,"Overstock","OK")))) -> No Activity
A13: BIG CHAIR | B13: 5001 (Maharaja) | C13: B-Silver | D13: 0 | E13: 0 | F13: 0 | G13: =IF(OR(E13="",E13=0),"n/a",IF(F13<0,"n/a",ROUND(F13/E13,1))) -> n/a | H13: =IF(F13<0,"Negative (check entry)",IF(OR(E13="",E13=0),IF(F13=0,"No Activity","OK"),IF(F13/E13<0.5,"Low Stock",IF(F13/E13>3,"Overstock","OK")))) -> No Activity
A14: BIG CHAIR | B14: 5001 (Maharaja) | C14: KR | D14: 0 | E14: 0 | F14: 0 | G14: =IF(OR(E14="",E14=0),"n/a",IF(F14<0,"n/a",ROUND(F14/E14,1))) -> n/a | H14: =IF(F14<0,"Negative (check entry)",IF(OR(E14="",E14=0),IF(F14=0,"No Activity","OK"),IF(F14/E14<0.5,"Low Stock",IF(F14/E14>3,"Overstock","OK")))) -> No Activity
... A79: BIG CHAIR | B79: 10001 New (Goli) | C79: G.Total | D79: 19776 | E79: 31344 | F79: 9914 | G79: =IF(OR(E79="",E79=0),"n/a",IF(F79<0,"n/a",ROUND(F79/E79,1))) -> 0.3 | H79: =IF(F79<0,"Negative (check entry)",IF(OR(E79="",E79=0),IF(F79=0,"No Activity","OK"),IF(F79/E79<0.5,"Low Stock",IF(F79/E79>3,"Overstock","OK")))) -> Low Stock
A80: Sumo | B80: Sumo - 301 | C80: S-W | D80: 0 | F80: 0 | G80: =IF(OR(E80="",E80=0),"n/a",IF(F80<0,"n/a",ROUND(F80/E80,1))) -> n/a | H80: =IF(F80<0,"Negative (check entry)",IF(OR(E80="",E80=0),IF(F80=0,"No Activity","OK"),IF(F80/E80<0.5,"Low Stock",IF(F80/E80>3,"Overstock","OK")))) -> No Activity
A81: Sumo | B81: Sumo - 301 | C81: Coloured | D81: 0 | F81: 0 | G81: =IF(OR(E81="",E81=0),"n/a",IF(F81<0,"n/a",ROUND(F81/E81,1))) -> n/a | H81: =IF(F81<0,"Negative (check entry)",IF(OR(E81="",E81=0),IF(F81=0,"No Activity","OK"),IF(F81/E81<0.5,"Low Stock",IF(F81/E81>3,"Overstock","OK")))) -> No Activity
A82: Sumo | B82: Sumo - 301 | C82: Red | D82: 0 | F82: 0 | G82: =IF(OR(E82="",E82=0),"n/a",IF(F82<0,"n/a",ROUND(F82/E82,1))) -> n/a | H82: =IF(F82<0,"Negative (check entry)",IF(OR(E82="",E82=0),IF(F82=0,"No Activity","OK"),IF(F82/E82<0.5,"Low Stock",IF(F82/E82>3,"Overstock","OK")))) -> No Activity
A83: Sumo | B83: Sumo - 301 | C83: P-Pink | D83: 0 | F83: 0 | G83: =IF(OR(E83="",E83=0),"n/a",IF(F83<0,"n/a",ROUND(F83/E83,1))) -> n/a | H83: =IF(F83<0,"Negative (check entry)",IF(OR(E83="",E83=0),IF(F83=0,"No Activity","OK"),IF(F83/E83<0.5,"Low Stock",IF(F83/E83>3,"Overstock","OK")))) -> No Activity
A84: Sumo | B84: Sumo - 301 | C84: B. Gold | D84: 0 | F84: 0 | G84: =IF(OR(E84="",E84=0),"n/a",IF(F84<0,"n/a",ROUND(F84/E84,1))) -> n/a | H84: =IF(F84<0,"Negative (check entry)",IF(OR(E84="",E84=0),IF(F84=0,"No Activity","OK"),IF(F84/E84<0.5,"Low Stock",IF(F84/E84>3,"Overstock","OK")))) -> No Activity
A85: Sumo | B85: Sumo - 301 | C85: Orange | D85: 0 | F85: 0 | G85: =IF(OR(E85="",E85=0),"n/a",IF(F85<0,"n/a",ROUND(F85/E85,1))) -> n/a | H85: =IF(F85<0,"Negative (check entry)",IF(OR(E85="",E85=0),IF(F85=0,"No Activity","OK"),IF(F85/E85<0.5,"Low Stock",IF(F85/E85>3,"Overstock","OK")))) -> No Activity
A86: Sumo | B86: Sumo - 301 | C86: P-White | D86: 0 | F86: 0 | G86: =IF(OR(E86="",E86=0),"n/a",IF(F86<0,"n/a",ROUND(F86/E86,1))) -> n/a | H86: =IF(F86<0,"Negative (check entry)",IF(OR(E86="",E86=0),IF(F86=0,"No Activity","OK"),IF(F86/E86<0.5,"Low Stock",IF(F86/E86>3,"Overstock","OK")))) -> No Activity
A87: Sumo | B87: Sumo - 301 | C87: Silver.B | D87: 0 | F87: 0 | G87: =IF(OR(E87="",E87=0),"n/a",IF(F87<0,"n/a",ROUND(F87/E87,1))) -> n/a | H87: =IF(F87<0,"Negative (check entry)",IF(OR(E87="",E87=0),IF(F87=0,"No Activity","OK"),IF(F87/E87<0.5,"Low Stock",IF(F87/E87>3,"Overstock","OK")))) -> No Activity
A88: Sumo | B88: Sumo - 301 | C88: P. Silver | D88: 0 | F88: 0 | G88: =IF(OR(E88="",E88=0),"n/a",IF(F88<0,"n/a",ROUND(F88/E88,1))) -> n/a | H88: =IF(F88<0,"Negative (check entry)",IF(OR(E88="",E88=0),IF(F88=0,"No Activity","OK"),IF(F88/E88<0.5,"Low Stock",IF(F88/E88>3,"Overstock","OK")))) -> No Activity
A89: Sumo | B89: Sumo - 301 | C89: A.Gold | D89: 208 | F89: 512 | G89: =IF(OR(E89="",E89=0),"n/a",IF(F89<0,"n/a",ROUND(F89/E89,1))) -> n/a | H89: =IF(F89<0,"Negative (check entry)",IF(OR(E89="",E89=0),IF(F89=0,"No Activity","OK"),IF(F89/E89<0.5,"Low Stock",IF(F89/E89>3,"Overstock","OK")))) -> OK
A90: Sumo | B90: Sumo - 301 | C90: P.Green | D90: 0 | F90: 0 | G90: =IF(OR(E90="",E90=0),"n/a",IF(F90<0,"n/a",ROUND(F90/E90,1))) -> n/a | H90: =IF(F90<0,"Negative (check entry)",IF(OR(E90="",E90=0),IF(F90=0,"No Activity","OK"),IF(F90/E90<0.5,"Low Stock",IF(F90/E90>3,"Overstock","OK")))) -> No Activity
A91: Sumo | B91: Sumo - 301 | C91: M.Bz | D91: 288 | F91: 288 | G91: =IF(OR(E91="",E91=0),"n/a",IF(F91<0,"n/a",ROUND(F91/E91,1))) -> n/a | H91: =IF(F91<0,"Negative (check entry)",IF(OR(E91="",E91=0),IF(F91=0,"No Activity","OK"),IF(F91/E91<0.5,"Low Stock",IF(F91/E91>3,"Overstock","OK")))) -> OK
... A99: Sumo | B99: Sumo - 301 | C99: G.Total | D99: 496 | F99: 2075 | G99: =IF(OR(E99="",E99=0),"n/a",IF(F99<0,"n/a",ROUND(F99/E99,1))) -> n/a | H99: =IF(F99<0,"Negative (check entry)",IF(OR(E99="",E99=0),IF(F99=0,"No Activity","OK"),IF(F99/E99<0.5,"Low Stock",IF(F99/E99>3,"Overstock","OK")))) -> OK
A100: XUV | B100: 8003 ClipON | C100: Br.Blue | D100: 0 | E100: 0 | F100: 0 | G100: =IF(OR(E100="",E100=0),"n/a",IF(F100<0,"n/a",ROUND(F100/E100,1))) -> n/a | H100: =IF(F100<0,"Negative (check entry)",IF(OR(E100="",E100=0),IF(F100=0,"No Activity","OK"),IF(F100/E100<0.5,"Low Stock",IF(F100/E100>3,"Overstock","OK")))) -> No Activity
A101: XUV | B101: 8003 ClipON | C101: Black Red | D101: 0 | E101: 0 | F101: 0 | G101: =IF(OR(E101="",E101=0),"n/a",IF(F101<0,"n/a",ROUND(F101/E101,1))) -> n/a | H101: =IF(F101<0,"Negative (check entry)",IF(OR(E101="",E101=0),IF(F101=0,"No Activity","OK"),IF(F101/E101<0.5,"Low Stock",IF(F101/E101>3,"Overstock","OK")))) -> No Activity
A102: XUV | B102: 8003 ClipON | C102: Br.Orange | D102: 0 | E102: 0 | F102: 0 | G102: =IF(OR(E102="",E102=0),"n/a",IF(F102<0,"n/a",ROUND(F102/E102,1))) -> n/a | H102: =IF(F102<0,"Negative (check entry)",IF(OR(E102="",E102=0),IF(F102=0,"No Activity","OK"),IF(F102/E102<0.5,"Low Stock",IF(F102/E102>3,"Overstock","OK")))) -> No Activity
A103: XUV | B103: 8003 ClipON | C103: Black Green | D103: 0 | E103: 0 | F103: 0 | G103: =IF(OR(E103="",E103=0),"n/a",IF(F103<0,"n/a",ROUND(F103/E103,1))) -> n/a | H103: =IF(F103<0,"Negative (check entry)",IF(OR(E103="",E103=0),IF(F103=0,"No Activity","OK"),IF(F103/E103<0.5,"Low Stock",IF(F103/E103>3,"Overstock","OK")))) -> No Activity
A104: XUV | B104: 8003 ClipON | C104: Br.Green | D104: 352 | E104: 256 | F104: 96 | G104: =IF(OR(E104="",E104=0),"n/a",IF(F104<0,"n/a",ROUND(F104/E104,1))) -> 0.4 | H104: =IF(F104<0,"Negative (check entry)",IF(OR(E104="",E104=0),IF(F104=0,"No Activity","OK"),IF(F104/E104<0.5,"Low Stock",IF(F104/E104>3,"Overstock","OK")))) -> Low Stock
A105: XUV | B105: 8003 ClipON | C105: Black Blue | D105: 0 | E105: 0 | F105: 0 | G105: =IF(OR(E105="",E105=0),"n/a",IF(F105<0,"n/a",ROUND(F105/E105,1))) -> n/a | H105: =IF(F105<0,"Negative (check entry)",IF(OR(E105="",E105=0),IF(F105=0,"No Activity","OK"),IF(F105/E105<0.5,"Low Stock",IF(F105/E105>3,"Overstock","OK")))) -> No Activity
A106: XUV | B106: 8003 ClipON | C106: Br.Red | D106: 0 | E106: 0 | F106: 0 | G106: =IF(OR(E106="",E106=0),"n/a",IF(F106<0,"n/a",ROUND(F106/E106,1))) -> n/a | H106: =IF(F106<0,"Negative (check entry)",IF(OR(E106="",E106=0),IF(F106=0,"No Activity","OK"),IF(F106/E106<0.5,"Low Stock",IF(F106/E106>3,"Overstock","OK")))) -> No Activity
A107: XUV | B107: 8003 ClipON | C107: Black Orange | D107: 0 | E107: 0 | F107: 0 | G107: =IF(OR(E107="",E107=0),"n/a",IF(F107<0,"n/a",ROUND(F107/E107,1))) -> n/a | H107: =IF(F107<0,"Negative (check entry)",IF(OR(E107="",E107=0),IF(F107=0,"No Activity","OK"),IF(F107/E107<0.5,"Low Stock",IF(F107/E107>3,"Overstock","OK")))) -> No Activity
A108: XUV | B108: 8002 (Y) | C108: S-W | D108: 0 | E108: 0 | F108: 0 | G108: =IF(OR(E108="",E108=0),"n/a",IF(F108<0,"n/a",ROUND(F108/E108,1))) -> n/a | H108: =IF(F108<0,"Negative (check entry)",IF(OR(E108="",E108=0),IF(F108=0,"No Activity","OK"),IF(F108/E108<0.5,"Low Stock",IF(F108/E108>3,"Overstock","OK")))) -> No Activity
A109: XUV | B109: 8002 (Y) | C109: T.W | D109: 304 | E109: 464 | F109: 480 | G109: =IF(OR(E109="",E109=0),"n/a",IF(F109<0,"n/a",ROUND(F109/E109,1))) -> 1 | H109: =IF(F109<0,"Negative (check entry)",IF(OR(E109="",E109=0),IF(F109=0,"No Activity","OK"),IF(F109/E109<0.5,"Low Stock",IF(F109/E109>3,"Overstock","OK")))) -> OK
A110: XUV | B110: 8002 (Y) | C110: B . Silver | D110: 560 | E110: 0 | F110: 560 | G110: =IF(OR(E110="",E110=0),"n/a",IF(F110<0,"n/a",ROUND(F110/E110,1))) -> n/a | H110: =IF(F110<0,"Negative (check entry)",IF(OR(E110="",E110=0),IF(F110=0,"No Activity","OK"),IF(F110/E110<0.5,"Low Stock",IF(F110/E110>3,"Overstock","OK")))) -> OK
A111: XUV | B111: 8002 (Y) | C111: B.Gold/Spl | D111: 1856 | E111: 528 | F111: 1328 | G111: =IF(OR(E111="",E111=0),"n/a",IF(F111<0,"n/a",ROUND(F111/E111,1))) -> 2.5 | H111: =IF(F111<0,"Negative (check entry)",IF(OR(E111="",E111=0),IF(F111=0,"No Activity","OK"),IF(F111/E111<0.5,"Low Stock",IF(F111/E111>3,"Overstock","OK")))) -> OK
...

Sheet Category Summary
A1: Totals rolled up per product sheet (i.e. per product line), pulled from Master SKU List.
A2: Product Sheet | B2: Total Opening Stock | C2: Total Sold This Period | D2: Total Closing Stock | E2: # SKUs | F2: # Flagged (Low/Negative)
A3: BIG CHAIR | B3: =SUMIF('Master SKU List'!A3:A698,A3,'Master SKU List'!D3:D698) -> 79104 | C3: =SUMIF('Master SKU List'!A3:A698,A3,'Master SKU List'!E3:E698) -> 125376 | D3: =SUMIF('Master SKU List'!A3:A698,A3,'Master SKU List'!F3:F698) -> 38745 | E3: =COUNTIF('Master SKU List'!A3:A698,A3) -> 77 | F3: =COUNTIFS('Master SKU List'!A3:A698,A3,'Master SKU List'!H3:H698,"Low Stock")+COUNTIFS('Master SKU List'!A3:A698,A3,'Master SKU List'!H3:H698,"Negative (check entry)") -> 12
A4: Sumo | B4: =SUMIF('Master SKU List'!A3:A698,A4,'Master SKU List'!D3:D698) -> 1984 | C4: =SUMIF('Master SKU List'!A3:A698,A4,'Master SKU List'!E3:E698) -> 0 | D4: =SUMIF('Master SKU List'!A3:A698,A4,'Master SKU List'!F3:F698) -> 8222 | E4: =COUNTIF('Master SKU List'!A3:A698,A4) -> 20 | F4: =COUNTIFS('Master SKU List'!A3:A698,A4,'Master SKU List'!H3:H698,"Low Stock")+COUNTIFS('Master SKU List'!A3:A698,A4,'Master SKU List'!H3:H698,"Negative (check entry)") -> 0
A5: XUV | B5: =SUMIF('Master SKU List'!A3:A698,A5,'Master SKU List'!D3:D698) -> 29056 | C5: =SUMIF('Master SKU List'!A3:A698,A5,'Master SKU List'!E3:E698) -> 14656 | D5: =SUMIF('Master SKU List'!A3:A698,A5,'Master SKU List'!F3:F698) -> 24373 | E5: =COUNTIF('Master SKU List'!A3:A698,A5) -> 29 | F5: =COUNTIFS('Master SKU List'!A3:A698,A5,'Master SKU List'!H3:H698,"Low Stock")+COUNTIFS('Master SKU List'!A3:A698,A5,'Master SKU List'!H3:H698,"Negative (check entry)") -> 1
A6: Innova | B6: =SUMIF('Master SKU List'!A3:A698,A6,'Master SKU List'!D3:D698) -> 0 | C6: =SUMIF('Master SKU List'!A3:A698,A6,'Master SKU List'!E3:E698) -> 0 | D6: =SUMIF('Master SKU List'!A3:A698,A6,'Master SKU List'!F3:F698) -> 0 | E6: =COUNTIF('Master SKU List'!A3:A698,A6) -> 21 | F6: =COUNTIFS('Master SKU List'!A3:A698,A6,'Master SKU List'!H3:H698,"Low Stock")+COUNTIFS('Master SKU List'!A3:A698,A6,'Master SKU List'!H3:H698,"Negative (check entry)") -> 0
A7: Garden Table | B7: =SUMIF('Master SKU List'!A3:A698,A7,'Master SKU List'!D3:D698) -> 13680 | C7: =SUMIF('Master SKU List'!A3:A698,A7,'Master SKU List'!E3:E698) -> 16176 | D7: =SUMIF('Master SKU List'!A3:A698,A7,'Master SKU List'!F3:F698) -> 3763 | E7: =COUNTIF('Master SKU List'!A3:A698,A7) -> 21 | F7: =COUNTIFS('Master SKU List'!A3:A698,A7,'Master SKU List'!H3:H698,"Low Stock")+COUNTIFS('Master SKU List'!A3:A698,A7,'Master SKU List'!H3:H698,"Negative (check entry)") -> 11
A8: Stool | B8: =SUMIF('Master SKU List'!A3:A698,A8,'Master SKU List'!D3:D698) -> 51680 | C8: =SUMIF('Master SKU List'!A3:A698,A8,'Master SKU List'!E3:E698) -> 8240 | D8: =SUMIF('Master SKU List'!A3:A698,A8,'Master SKU List'!F3:F698) -> 43440 | E8: =COUNTIF('Master SKU List'!A3:A698,A8) -> 21 | F8: =COUNTIFS('Master SKU List'!A3:A698,A8,'Master SKU List'!H3:H698,"Low Stock")+COUNTIFS('Master SKU List'!A3:A698,A8,'Master SKU List'!H3:H698,"Negative (check entry)") -> 0
A9: Activa | B9: =SUMIF('Master SKU List'!A3:A698,A9,'Master SKU List'!D3:D698) -> 44928 | C9: =SUMIF('Master SKU List'!A3:A698,A9,'Master SKU List'!E3:E698) -> 49792 | D9: =SUMIF('Master SKU List'!A3:A698,A9,'Master SKU List'!F3:F698) -> 40807 | E9: =COUNTIF('Master SKU List'!A3:A698,A9) -> 26 | F9: =COUNTIFS('Master SKU List'!A3:A698,A9,'Master SKU List'!H3:H698,"Low Stock")+COUNTIFS('Master SKU List'!A3:A698,A9,'Master SKU List'!H3:H698,"Negative (check entry)") -> 4
A10: Small Chair | B10: =SUMIF('Master SKU List'!A3:A698,A10,'Master SKU List'!D3:D698) -> 35760 | C10: =SUMIF('Master SKU List'!A3:A698,A10,'Master SKU List'!E3:E698) -> 36783 | D10: =SUMIF('Master SKU List'!A3:A698,A10,'Master SKU List'!F3:F698) -> 14644.9 | E10: =COUNTIF('Master SKU List'!A3:A698,A10) -> 29 | F10: =COUNTIFS('Master SKU List'!A3:A698,A10,'Master SKU List'!H3:H698,"Low Stock")+COUNTIFS('Master SKU List'!A3:A698,A10,'Master SKU List'!H3:H698,"Negative (check entry)") -> 7
A11: EV Chair | B11: =SUMIF('Master SKU List'!A3:A698,A11,'Master SKU List'!D3:D698) -> 12800 | C11: =SUMIF('Master SKU List'!A3:A698,A11,'Master SKU List'!E3:E698) -> 4864 | D11: =SUMIF('Master SKU List'!A3:A698,A11,'Master SKU List'!F3:F698) -> 7936 | E11: =COUNTIF('Master SKU List'!A3:A698,A11) -> 22 | F11: =COUNTIFS('Master SKU List'!A3:A698,A11,'Master SKU List'!H3:H698,"Low Stock")+COUNTIFS('Master SKU List'!A3:A698,A11,'Master SKU List'!H3:H698,"Negative (check entry)") -> 4
A12: Aless | B12: =SUMIF('Master SKU List'!A3:A698,A12,'Master SKU List'!D3:D698) -> 26560 | C12: =SUMIF('Master SKU List'!A3:A698,A12,'Master SKU List'!E3:E698) -> 48800 | D12: =SUMIF('Master SKU List'!A3:A698,A12,'Master SKU List'!F3:F698) -> 16584 | E12: =COUNTIF('Master SKU List'!A3:A698,A12) -> 29 | F12: =COUNTIFS('Master SKU List'!A3:A698,A12,'Master SKU List'!H3:H698,"Low Stock")+COUNTIFS('Master SKU List'!A3:A698,A12,'Master SKU List'!H3:H698,"Negative (check entry)") -> 6
A13: Tea Table | B13: =SUMIF('Master SKU List'!A3:A698,A13,'Master SKU List'!D3:D698) -> 9264 | C13: =SUMIF('Master SKU List'!A3:A698,A13,'Master SKU List'!E3:E698) -> 16896 | D13: =SUMIF('Master SKU List'!A3:A698,A13,'Master SKU List'!F3:F698) -> 10945 | E13: =COUNTIF('Master SKU List'!A3:A698,A13) -> 20 | F13: =COUNTIFS('Master SKU List'!A3:A698,A13,'Master SKU List'!H3:H698,"Low Stock")+COUNTIFS('Master SKU List'!A3:A698,A13,'Master SKU List'!H3:H698,"Negative (check entry)") -> 2
A14: Chota Heritage | B14: =SUMIF('Master SKU List'!A3:A698,A14,'Master SKU List'!D3:D698) -> 1472 | C14: =SUMIF('Master SKU List'!A3:A698,A14,'Master SKU List'!E3:E698) -> 2880 | D14: =SUMIF('Master SKU List'!A3:A698,A14,'Master SKU List'!F3:F698) -> 9710 | E14: =COUNTIF('Master SKU List'!A3:A698,A14) -> 17 | F14: =COUNTIFS('Master SKU List'!A3:A698,A14,'Master SKU List'!H3:H698,"Low Stock")+COUNTIFS('Master SKU List'!A3:A698,A14,'Master SKU List'!H3:H698,"Negative (check entry)") -> 0
A15: M.P.Stool | B15: =SUMIF('Master SKU List'!A3:A698,A15,'Master SKU List'!D3:D698) -> 12800 | C15: =SUMIF('Master SKU List'!A3:A698,A15,'Master SKU List'!E3:E698) -> 960 | D15: =SUMIF('Master SKU List'!A3:A698,A15,'Master SKU List'!F3:F698) -> 11840 | E15: =COUNTIF('Master SKU List'!A3:A698,A15) -> 23 | F15: =COUNTIFS('Master SKU List'!A3:A698,A15,'Master SKU List'!H3:H698,"Low Stock")+COUNTIFS('Master SKU List'!A3:A698,A15,'Master SKU List'!H3:H698,"Negative (check entry)") -> 0
A16: Yoddha | B16: =SUMIF('Master SKU List'!A3:A698,A16,'Master SKU List'!D3:D698) -> 14016 | C16: =SUMIF('Master SKU List'!A3:A698,A16,'Master SKU List'!E3:E698) -> 27792 | D16: =SUMIF('Master SKU List'!A3:A698,A16,'Master SKU List'!F3:F698) -> 17076 | E16: =COUNTIF('Master SKU List'!A3:A698,A16) -> 28 | F16: =COUNTIFS('Master SKU List'!A3:A698,A16,'Master SKU List'!H3:H698,"Low Stock")+COUNTIFS('Master SKU List'!A3:A698,A16,'Master SKU List'!H3:H698,"Negative (check entry)") -> 4
A17: ClipON Stool | B17: =SUMIF('Master SKU List'!A3:A698,A17,'Master SKU List'!D3:D698) -> 15040 | C17: =SUMIF('Master SKU List'!A3:A698,A17,'Master SKU List'!E3:E698) -> 5760 | D17: =SUMIF('Master SKU List'!A3:A698,A17,'Master SKU List'!F3:F698) -> 9280 | E17: =COUNTIF('Master SKU List'!A3:A698,A17) -> 22 | F17: =COUNTIFS('Master SKU List'!A3:A698,A17,'Master SKU List'!H3:H698,"Low Stock")+COUNTIFS('Master SKU List'!A3:A698,A17,'Master SKU List'!H3:H698,"Negative (check entry)") -> 1
A18: Baby Chair | B18: =SUMIF('Master SKU List'!A3:A698,A18,'Master SKU List'!D3:D698) -> 3600 | C18: =SUMIF('Master SKU List'!A3:A698,A18,'Master SKU List'!E3:E698) -> 720 | D18: =SUMIF('Master SKU List'!A3:A698,A18,'Master SKU List'!F3:F698) -> 2880 | E18: =COUNTIF('Master SKU List'!A3:A698,A18) -> 22 | F18: =COUNTIFS('Master SKU List'!A3:A698,A18,'Master SKU List'!H3:H698,"Low Stock")+COUNTIFS('Master SKU List'!A3:A698,A18,'Master SKU List'!H3:H698,"Negative (check entry)") -> 0
A19: BABA CHAIR 1 | B19: =SUMIF('Master SKU List'!A3:A698,A19,'Master SKU List'!D3:D698) -> 36560 | C19: =SUMIF('Master SKU List'!A3:A698,A19,'Master SKU List'!E3:E698) -> 21600 | D19: =SUMIF('Master SKU List'!A3:A698,A19,'Master SKU List'!F3:F698) -> 14960 | E19: =COUNTIF('Master SKU List'!A3:A698,A19) -> 21 | F19: =COUNTIFS('Master SKU List'!A3:A698,A19,'Master SKU List'!H3:H698,"Low Stock")+COUNTIFS('Master SKU List'!A3:A698,A19,'Master SKU List'!H3:H698,"Negative (check entry)") -> 3
A20: Jordan New | B20: =SUMIF('Master SKU List'!A3:A698,A20,'Master SKU List'!D3:D698) -> 13296 | C20: =SUMIF('Master SKU List'!A3:A698,A20,'Master SKU List'!E3:E698) -> 17088 | D20: =SUMIF('Master SKU List'!A3:A698,A20,'Master SKU List'!F3:F698) -> 15746 | E20: =COUNTIF('Master SKU List'!A3:A698,A20) -> 28 | F20: =COUNTIFS('Master SKU List'!A3:A698,A20,'Master SKU List'!H3:H698,"Low Stock")+COUNTIFS('Master SKU List'!A3:A698,A20,'Master SKU List'!H3:H698,"Negative (check entry)") -> 4
A21: Jordan Chair | B21: =SUMIF('Master SKU List'!A3:A698,A21,'Master SKU List'!D3:D698) -> 11184 | C21: =SUMIF('Master SKU List'!A3:A698,A21,'Master SKU List'!E3:E698) -> 4032 | D21: =SUMIF('Master SKU List'!A3:A698,A21,'Master SKU List'!F3:F698) -> 9761 | E21: =COUNTIF('Master SKU List'!A3:A698,A21) -> 25 | F21: =COUNTIFS('Master SKU List'!A3:A698,A21,'Master SKU List'!H3:H698,"Low Stock")+COUNTIFS('Master SKU List'!A3:A698,A21,'Master SKU List'!H3:H698,"Negative (check entry)") -> 1
A22: High cros | B22: =SUMIF('Master SKU List'!A3:A698,A22,'Master SKU List'!D3:D698) -> 20320 | C22: =SUMIF('Master SKU List'!A3:A698,A22,'Master SKU List'!E3:E698) -> 11200 | D22: =SUMIF('Master SKU List'!A3:A698,A22,'Master SKU List'!F3:F698) -> 9120 | E22: =COUNTIF('Master SKU List'!A3:A698,A22) -> 24 | F22: =COUNTIFS('Master SKU List'!A3:A698,A22,'Master SKU List'!H3:H698,"Low Stock")+COUNTIFS('Master SKU List'!A3:A698,A22,'Master SKU List'!H3:H698,"Negative (check entry)") -> 4
A23: Ring Table | B23: =SUMIF('Master SKU List'!A3:A698,A23,'Master SKU List'!D3:D698) -> 7728 | C23: =SUMIF('Master SKU List'!A3:A698,A23,'Master SKU List'!E3:E698) -> 3120 | D23: =SUMIF('Master SKU List'!A3:A698,A23,'Master SKU List'!F3:F698) -> 14953 | E23: =COUNTIF('Master SKU List'!A3:A698,A23) -> 20 | F23: =COUNTIFS('Master SKU List'!A3:A698,A23,'Master SKU List'!H3:H698,"Low Stock")+COUNTIFS('Master SKU List'!A3:A698,A23,'Master SKU List'!H3:H698,"Negative (check entry)") -> 0
A24: ARM LESS SUMO | B24: =SUMIF('Master SKU List'!A3:A698,A24,'Master SKU List'!D3:D698) -> 15680 | C24: =SUMIF('Master SKU List'!A3:A698,A24,'Master SKU List'!E3:E698) -> 6240 | D24: =SUMIF('Master SKU List'!A3:A698,A24,'Master SKU List'!F3:F698) -> 24799 | E24: =COUNTIF('Master SKU List'!A3:A698,A24) -> 24 | F24: =COUNTIFS('Master SKU List'!A3:A698,A24,'Master SKU List'!H3:H698,"Low Stock")+COUNTIFS('Master SKU List'!A3:A698,A24,'Master SKU List'!H3:H698,"Negative (check entry)") -> 3
A25: JIO TABLE | B25: =SUMIF('Master SKU List'!A3:A698,A25,'Master SKU List'!D3:D698) -> 22864 | C25: =SUMIF('Master SKU List'!A3:A698,A25,'Master SKU List'!E3:E698) -> 728 | D25: =SUMIF('Master SKU List'!A3:A698,A25,'Master SKU List'!F3:F698) -> 22136 | E25: =COUNTIF('Master SKU List'!A3:A698,A25) -> 28 | F25: =COUNTIFS('Master SKU List'!A3:A698,A25,'Master SKU List'!H3:H698,"Low Stock")+COUNTIFS('Master SKU List'!A3:A698,A25,'Master SKU List'!H3:H698,"Negative (check entry)") -> 0
A26: Dining Table | B26: =SUMIF('Master SKU List'!A3:A698,A26,'Master SKU List'!D3:D698) -> 9400 | C26: =SUMIF('Master SKU List'!A3:A698,A26,'Master SKU List'!E3:E698) -> 1960 | D26: =SUMIF('Master SKU List'!A3:A698,A26,'Master SKU List'!F3:F698) -> 7440 | E26: =COUNTIF('Master SKU List'!A3:A698,A26) -> 28 | F26: =COUNTIFS('Master SKU List'!A3:A698,A26,'Master SKU List'!H3:H698,"Low Stock")+COUNTIFS('Master SKU List'!A3:A698,A26,'Master SKU List'!H3:H698,"Negative (check entry)") -> 1
A27: Web Chair | B27: =SUMIF('Master SKU List'!A3:A698,A27,'Master SKU List'!D3:D698) -> 11136 | C27: =SUMIF('Master SKU List'!A3:A698,A27,'Master SKU List'!E3:E698) -> 1080 | D27: =SUMIF('Master SKU List'!A3:A698,A27,'Master SKU List'!F3:F698) -> 10056 | E27: =COUNTIF('Master SKU List'!A3:A698,A27) -> 17 | F27: =COUNTIFS('Master SKU List'!A3:A698,A27,'Master SKU List'!H3:H698,"Low Stock")+COUNTIFS('Master SKU List'!A3:A698,A27,'Master SKU List'!H3:H698,"Negative (check entry)") -> 0
A28: F.Stand & C Table | B28: =SUMIF('Master SKU List'!A3:A698,A28,'Master SKU List'!D3:D698) -> 10048 | C28: =SUMIF('Master SKU List'!A3:A698,A28,'Master SKU List'!E3:E698) -> 18912 | D28: =SUMIF('Master SKU List'!A3:A698,A28,'Master SKU List'!F3:F698) -> 3094 | E28: =COUNTIF('Master SKU List'!A3:A698,A28) -> 26 | F28: =COUNTIFS('Master SKU List'!A3:A698,A28,'Master SKU List'!H3:H698,"Low Stock")+COUNTIFS('Master SKU List'!A3:A698,A28,'Master SKU List'!H3:H698,"Negative (check entry)") -> 10
A29: Fruit Crate | B29: =SUMIF('Master SKU List'!A3:A698,A29,'Master SKU List'!D3:D698) -> 0 | C29: =SUMIF('Master SKU List'!A3:A698,A29,'Master SKU List'!E3:E698) -> 0 | D29: =SUMIF('Master SKU List'!A3:A698,A29,'Master SKU List'!F3:F698) -> 0 | E29: =COUNTIF('Master SKU List'!A3:A698,A29) -> 28 | F29: =COUNTIFS('Master SKU List'!A3:A698,A29,'Master SKU List'!H3:H698,"Low Stock")+COUNTIFS('Master SKU List'!A3:A698,A29,'Master SKU List'!H3:H698,"Negative (check entry)") -> 0
