Workbook

Sheet M-1
A1: 46113
BC2: 1 | BD2: 4 | BE2: 2026
A3: M-1 | E3: Fresh Piece | AA3: Colour Mix Piece | AW3: Rejection Piece
A4: DATE | B4: SHIFT | C4: TOTAL PIECE | E4: Big Chair | F4: Big Maharaja | G4: XUV | H4: Chota Heritage | I4: Activa | J4: EV.Chair | K4: High Cross | L4: INNOVA | M4: Stool | N4: Baba Chair | O4: Baby Chair | P4: Fridge Stand | Q4: Jordan Chair | R4: Heritage | S4: J.New | T4: Fruit Crate | U4: ALess | V4: WEB CHAIR | W4: C.Table | X4: Table | Y4: Garden Table | Z4: Small Chair | AA4: Big Chair | AB4: Big Maharaja | AC4: XUV | AD4: Chota Heritage | AE4: Activa | AF4: EV.Chair | AG4: High Cross | AH4: INNOVA | AI4: Stool | AJ4: Baba Chair | AK4: Baby Chair | AL4: Fridge Stand | AM4: Jordan Chair | AN4: =R4 -> Heritage | AO4: J.New | AP4: =T4 -> Fruit Crate | AQ4: =U4 -> ALess | AR4: WEB CHAIR | AS4: C.Table | AT4: Table | AU4: Garden Table | AV4: Small Chair | AW4: Big / MJ/Heritage/XUV/Ev | AX4: Small Chair/Aless/CH | AY4: Fruit Crate/Stool/F.S | AZ4: Table/T.New | BA4: Net Fresh Piece | BB4: Net Usable Prod. | BC4: MODEL | BD4: COLOR | BE4: REMARKS
A5: 46116 | B5: Day | C5: =SUM(D5:D6) -> 180 | D5: =SUM(E5:AZ5) -> 180 | Q5: 156 | AX5: 24 | BA5: =SUM(E5:Z6) -> 156 | BB5: =SUM(E5:AV6) -> 156 | BC5: 9003 | BD5: G.B | BE5: N/A
B6: Night | D6: =SUM(E6:AZ6) -> 0
A7: 46121 | B7: Day | C7: =SUM(D7:D10) -> 272 | D7: =SUM(E7:AZ7) -> 272 | Q7: 252 | AM7: 3 | AX7: 17 | BA7: =SUM(E7:Z10) -> 252 | BB7: =SUM(E7:AV10) -> 255 | BC7: 9003 | BD7: G.B | BE7: N/A
B8: Night | D8: =SUM(E8:AZ8) -> 0
B9: Night | D9: =SUM(E9:AZ9) -> 0
B10: Night | D10: =SUM(E10:AZ10) -> 0
A11: 46122 | B11: Day | C11: =SUM(D11:D14) -> 703 | D11: =SUM(E11:AZ11) -> 227 | Q11: 216 | AX11: 11 | BA11: =SUM(E11:Z14) -> 680 | BB11: =SUM(E11:AV14) -> 687 | BC11: 9003 | BD11: G.B | BE11: N/A
B12: Night | D12: =SUM(E12:AZ12) -> 476 | W12: 464 | AS12: 7 | AZ12: 5 | BC12: C.T | BD12: A.G
B13: Night | D13: =SUM(E13:AZ13) -> 0
B14: Night | D14: =SUM(E14:AZ14) -> 0
A15: 46123 | B15: Day | C15: =SUM(D15:D18) -> 704 | D15: =SUM(E15:AZ15) -> 256 | W15: 256 | BA15: =SUM(E15:Z18) -> 688 | BB15: =SUM(E15:AV18) -> 695 | BC15: C.T | BD15: A.G, BROWN | BE15: N/A
B16: Night | D16: =SUM(E16:AZ16) -> 448 | W16: =368+64 -> 432 | AS16: =4+3 -> 7 | AZ16: 9
B17: Night | D17: =SUM(E17:AZ17) -> 0
B18: Night | D18: =SUM(E18:AZ18) -> 0
A19: 46124 | B19: Day | C19: =SUM(D19:D21) -> 788 | D19: =SUM(E19:AZ19) -> 322 | W19: 320 | AZ19: 2 | BA19: =SUM(E19:Z21) -> 768 | BB19: =SUM(E19:AV21) -> 768 | BC19: C.T | BD19: BROWN | BE19: N/A
B20: Night | D20: =SUM(E20:AZ20) -> 466 | W20: 448 | AZ20: 18
B21: Night | D21: =SUM(E21:AZ21) -> 0
A22: 46125 | B22: Day | C22: =SUM(D22:D24) -> 980 | D22: =SUM(E22:AZ22) -> 497 | W22: 496 | AZ22: 1 | BA22: =SUM(E22:Z24) -> 976 | BB22: =SUM(E22:AV24) -> 976 | BC22: C.T | BD22: BROWN | BE22: N/A
B23: Night | D23: =SUM(E23:AZ23) -> 483 | W23: 480 | AZ23: 3
B24: Night | D24: =SUM(E24:AZ24) -> 0
A25: 46126 | B25: Day | C25: =SUM(D25:D28) -> 747 | D25: =SUM(E25:AZ25) -> 64 | W25: 64 | BA25: =SUM(E25:Z28) -> 700 | BB25: =SUM(E25:AV28) -> 703 | BC25: C.T | BD25: BROWN | BE25: N/A
B26: Night | D26: =SUM(E26:AZ26) -> 193 | Y26: 156 | AU26: 3 | AZ26: 34 | BC26: G.T | BD26: BROWN
B27: Night | D27: =SUM(E27:AZ27) -> 490 | Y27: 480 | AZ27: 10
B28: Night | D28: =SUM(E28:AZ28) -> 0
A29: 46127 | B29: Day | C29: =SUM(D29:D32) -> 826 | D29: =SUM(E29:AZ29) -> 365 | Y29: =132+216 -> 348 | AU29: 17 | BA29: =SUM(E29:Z32) -> 804 | BB29: =SUM(E29:AV32) -> 826 | BC29: G.T | BD29: BROWN, A.G | BE29: N/A
B30: Night | D30: =SUM(E30:AZ30) -> 461 | Y30: 456 | AU30: 5
B31: Night | D31: =SUM(E31:AZ31) -> 0
B32: Night | D32: =SUM(E32:AZ32) -> 0
A33: 46128 | B33: Day | C33: =SUM(D33:D35) -> 84 | D33: =SUM(E33:AZ33) -> 84 | Y33: 84 | BA33: =SUM(E33:Z35) -> 84 | BB33: =SUM(E33:AV35) -> 84 | BC33: G.T | BD33: A.G | BE33: N/A
B34: Night | D34: =SUM(E34:AZ34) -> 0
B35: Night | D35: =SUM(E35:AZ35) -> 0
A36: 46129 | B36: Day | C36: =SUM(D36:D39) -> 74 | D36: =SUM(E36:AZ36) -> 74 | G36: 64 | AC36: 2 | AW36: 8 | BA36: =SUM(E36:Z39) -> 64 | BB36: =SUM(E36:AV39) -> 66 | BC36: 8002 | BD36: A.G | BE36: N/A
B37: Day | D37: =SUM(E37:AZ37) -> 0
B38: Night | D38: =SUM(E38:AZ38) -> 0
B39: Night | D39: =SUM(E39:AZ39) -> 0
A40: 46130 | B40: Day | C40: =SUM(D40:D43) -> 782 | D40: =SUM(E40:AZ40) -> 516 | G40: 496 | AC40: 3 | AW40: 17 | BA40: =SUM(E40:Z43) -> 736 | BB40: =SUM(E40:AV43) -> 745 | BC40: 8002 | BD40: A.G | BE40: N/A
...

Sheet M-2
A1: 46113
AY2: 1 | AZ2: 4 | BA2: 2025
A3: M-2 | E3: Fresh Piece | Y3: Colour Mix Piece | AS3: Rejection Piece
A4: DATE | B4: SHIFT | C4: TOTAL PIECE | E4: Big Chair | F4: Big Maharaja | G4: XUV | H4: Chota Heritage | I4: Innova | J4: Stool | K4: EV | L4: Fridge Stand | M4: Jordan Chair | N4: Heritage | O4: Activa | P4: J.New | Q4: Fruit Crate | R4: ALess | S4: D.Table | T4: D.Leg.Can. | U4: Small Chair | V4: C.Table | W4: Table | X4: Garden Table | Y4: Big Chair | Z4: Big Maharaja | AA4: XUV | AB4: Chota Heritage | AC4: Innova | AD4: Stool | AE4: EV | AF4: Fridge Stand | AG4: Jordan Chair | AH4: Heritage | AI4: J.New | AJ4: Activa | AK4: Fruit Crate | AL4: Aless | AM4: D.Table | AN4: D.Leg.Can. | AO4: Small Chair | AP4: C.Table | AQ4: Table | AR4: Garden Table | AS4: Big Chair/Mj/Heritage/Act | AT4: Small Chair/Aless/CH | AU4: Fruit Crate | AV4: Table/T.New | AW4: Net Fresh Piece | AX4: Net Usable Prod. | AY4: MODEL | AZ4: COLOR | BA4: REMARKS
A5: 46116 | B5: Day | C5: =SUM(D5:D7) -> 797 | D5: =SUM(E5:AV5) -> 309 | U5: 300 | AO5: 2 | AT5: 7 | AW5: =SUM(E5:X7) -> 780 | AX5: =SUM(E5:AR7) -> 786 | AY5: 402 | AZ5: A.G | BA5: N/A
B6: Night | D6: =SUM(E6:AV6) -> 488 | U6: 480 | AO6: 4 | AT6: 4
B7: Night | D7: =SUM(E7:AV7) -> 0
A8: 46117 | B8: Day | C8: =SUM(D8:D11) -> 1071 | D8: =SUM(E8:AV8) -> 490 | U8: 480 | AO8: 5 | AT8: 5 | AW8: =SUM(E8:X11) -> 1040 | AX8: =SUM(E8:AR11) -> 1050 | AY8: 402 | AZ8: A.G | BA8: N/A
B9: Night | D9: =SUM(E9:AV9) -> 581 | U9: 560 | AO9: 5 | AT9: 16
B10: Night | D10: =SUM(E10:AV10) -> 0
B11: Night | D11: =SUM(E11:AV11) -> 0
A12: 46118 | B12: Day | C12: =SUM(D12:D14) -> 1025 | D12: =SUM(E12:AV12) -> 473 | U12: =320+120 -> 440 | AO12: =3+10 -> 13 | AT12: =13+7 -> 20 | AW12: =SUM(E12:X14) -> 960 | AX12: =SUM(E12:AR14) -> 973 | AY12: 402 | AZ12: A.G , BROWN | BA12: N/A
B13: Night | D13: =SUM(E13:AV13) -> 552 | U13: 520 | AT13: 32
B14: Night | D14: =SUM(E14:AV14) -> 0
A15: 46119 | B15: Day | C15: =SUM(D15:D19) -> 1153 | D15: =SUM(E15:AV15) -> 549 | U15: 540 | AT15: 9 | AW15: =SUM(E15:X19) -> 1120 | AX15: =SUM(E15:AR19) -> 1120 | AY15: 402 | AZ15: BROWN | BA15: N/A
B16: Night | D16: =SUM(E16:AV16) -> 604 | U16: 580 | AT16: 24
B17: Day | D17: =SUM(E17:AV17) -> 0
B18: Night | D18: =SUM(E18:AV18) -> 0
B19: Night | D19: =SUM(E19:AV19) -> 0
A20: 46120 | B20: Day | C20: =SUM(D20:D22) -> 963 | D20: =SUM(E20:AV20) -> 485 | U20: 460 | AT20: 25 | AW20: =SUM(E20:X22) -> 900 | AX20: =SUM(E20:AR22) -> 900 | AY20: 402 | AZ20: BROWN | BA20: N/A
B21: Night | D21: =SUM(E21:AV21) -> 478 | U21: 440 | AT21: 38
B22: Night | D22: =SUM(E22:AV22) -> 0
A23: 46125 | B23: Day | C23: =SUM(D23:D25) -> 622 | D23: =SUM(E23:AV23) -> 622 | U23: 580 | AO23: 12 | AT23: 30 | AW23: =SUM(E23:X25) -> 580 | AX23: =SUM(E23:AR25) -> 592 | AY23: 402 | AZ23: A.G | BA23: N/A
B24: Night | D24: =SUM(E24:AV24) -> 0
B25: Night | D25: =SUM(E25:AV25) -> 0
A26: 46126 | B26: Day | C26: =SUM(D26:D29) -> 631 | D26: =SUM(E26:AV26) -> 198 | U26: 180 | AT26: 18 | AW26: =SUM(E26:X29) -> 596 | AX26: =SUM(E26:AR29) -> 596 | AY26: 402 | AZ26: A.G
B27: Night | D27: =SUM(E27:AV27) -> 433 | E27: 416 | AS27: 17 | AY27: 10001 | AZ27: OK
B28: Night | D28: =SUM(E28:AV28) -> 0
B29: Night | D29: =SUM(E29:AV29) -> 0
A30: 46127 | B30: Day | C30: =SUM(D30:D33) -> 809 | D30: =SUM(E30:AV30) -> 336 | E30: 320 | AS30: 16 | AW30: =SUM(E30:X33) -> 768 | AX30: =SUM(E30:AR33) -> 768 | AY30: 10001 | AZ30: OK | BA30: N/A
B31: Night | D31: =SUM(E31:AV31) -> 473 | E31: 448 | AS31: 25
B32: Night | D32: =SUM(E32:AV32) -> 0
B33: Night | D33: =SUM(E33:AV33) -> 0
A34: 46128 | B34: Day | C34: =SUM(D34:D35) -> 921 | D34: =SUM(E34:AV34) -> 539 | E34: 528 | AS34: 11 | AW34: =SUM(E34:X37) -> 880 | AX34: =SUM(E34:AR37) -> 880 | AY34: 10001 | AZ34: OK | BA34: N/A
B35: Night | D35: =SUM(E35:AV35) -> 382 | E35: 352 | AS35: 30
B36: Night | D36: =SUM(E36:AV36) -> 0
B37: Night | D37: =SUM(E37:AV37) -> 0
A38: 46129 | B38: Day | C38: =SUM(D38:D42) -> 943 | D38: =SUM(E38:AV38) -> 563 | E38: 560 | AS38: 3 | AW38: =SUM(E38:X42) -> 928 | AX38: =SUM(E38:AR42) -> 928 | AY38: 10001 | AZ38: OK | BA38: N/A
B39: Night | D39: =SUM(E39:AV39) -> 380 | E39: 368 | AS39: 12
B40: Night | D40: =SUM(E40:AV40) -> 0
...

Sheet M-3
A1: 46113
BJ2: 1 | BK2: 4 | BL2: 2025
A3: M 3 | E3: Fresh Piece | AD3: Colour Mix Piece | BD3: Rejection Piece
A4: DATE | B4: SHIFT | C4: TOTAL PIECE | E4: Big Chair | F4: Big Maharaja | G4: XUV | H4: Sumo | I4: Chota Heritage | J4: Ring Table | K4: E.V.Chair | L4: Yoddha | M4: Stool | N4: AL SUMO | O4: M.P.Stool | P4: Fridge Stand | Q4: Baby Chair | R4: Baby Chair New | S4: Jordan Chair | T4: JIO TABLE | U4: J.New | V4: Activa | W4: Fruit Crate | X4: ALess | Y4: D.Table Top | Z4: C. Table | AA4: Table | AB4: Garden Table | AC4: Small Chair | AD4: Big Chair | AE4: Big Maharaja | AF4: XUV | AG4: Sumo | AH4: Chota Heritage | AI4: Ring Table | AJ4: Yoddha | AK4: AL SUMO | AL4: New Stool | AM4: M.P.Stool | AN4: Fridge Stand | AO4: Baby Chair | AP4: Baby Chair New | AQ4: JIO TABLE | AR4: J.New | AS4: Jordan Chair | AT4: Activa | AU4: Fruit Crate | AV4: Aless | AW4: Inv | AX4: E.V.Chair | AY4: C.Table | AZ4: D.T | BA4: Table | BB4: Garden Table | BC4: Small Chair | BD4: Big Chair/Mj/Heritage | BE4: Jordan Chair/Aless/CH | BF4: Fruit Crate/Yoddha | BG4: Table/T.New | BH4: Net Fresh Piece | BI4: Net Usable Prod. | BJ4: MODEL | BK4: COLOR | BL4: REMARKS
A5: 46116 | B5: Day | C5: =SUM(D5:D7) -> 661 | D5: =SUM(E5:BG5) -> 266 | U5: 264 | AR5: 2 | BH5: =SUM(E5:AC7) -> 648 | BI5: =SUM(E5:BC7) -> 657 | BJ5: 1003 | BK5: T.W | BL5: N/A
B6: Night | D6: =SUM(E6:BG6) -> 395 | U6: =360+24 -> 384 | AR6: =3+4 -> 7 | BE6: 4
B7: Night | D7: =SUM(E7:BG7) -> 0
A8: 46117 | B8: Day | C8: =SUM(D8:D10) -> 604 | D8: =SUM(E8:BG8) -> 436 | U8: 432 | BE8: 4 | BH8: =SUM(E8:AC10) -> 600 | BI8: =SUM(E8:BC10) -> 600 | BJ8: 1003 | BK8: A.G | BL8: N/A
B9: Night | D9: =SUM(E9:BG9) -> 168 | U9: 168
B10: Night | D10: =SUM(E10:BG10) -> 0
A11: 46120 | B11: Day | C11: =SUM(D11:D14) -> 330 | D11: =SUM(E11:BG11) -> 330 | U11: 324 | AR11: 5 | BE11: 1 | BH11: =SUM(E11:AC14) -> 324 | BI11: =SUM(E11:BC14) -> 329 | BJ11: 1003 | BK11: G.B
B12: Night | D12: =SUM(E12:BG12) -> 0
B13: Night | D13: =SUM(E13:BG13) -> 0
B14: Night | D14: =SUM(E14:BG14) -> 0
A15: 46121 | B15: Day | C15: =SUM(D15:D19) -> 776 | D15: =SUM(E15:BG15) -> 280 | U15: 276 | BE15: 4 | BH15: =SUM(E15:AC19) -> 768 | BI15: =SUM(E15:BC19) -> 768 | BJ15: 1003 | BK15: G.B | BL15: N/A
B16: Night | D16: =SUM(E16:BG16) -> 496 | U16: 492 | BE16: 4
B17: Night | D17: =SUM(E17:BG17) -> 0
B18: Night | D18: =SUM(E18:BG18) -> 0
B19: Night | D19: =SUM(E19:BG19) -> 0
A20: 46122 | B20: Day | C20: =SUM(D20:D22) -> 602 | D20: =SUM(E20:BG20) -> 36 | U20: 36 | BH20: =SUM(E20:AC22) -> 536 | BI20: =SUM(E20:BC22) -> 542 | BJ20: 1003 | BK20: G.B | BL20: N/A
B21: Night | D21: =SUM(E21:BG21) -> 208 | N21: 160 | AK21: 6 | BE21: 42 | BJ21: AL SUMO | BK21: G.B
B22: Night | D22: =SUM(E22:BG22) -> 358 | N22: 340 | BE22: 18
A23: 46123 | B23: Day | C23: =SUM(D23:D26) -> 617 | D23: =SUM(E23:BG23) -> 234 | N23: 220 | AK23: 3 | BE23: 11 | BH23: =SUM(E23:AC26) -> 600 | BI23: =SUM(E23:BC26) -> 603 | BJ23: AL SUMO | BK23: G.B | BL23: N/A
B24: Day | D24: =SUM(E24:BG24) -> 383 | N24: 380 | BE24: 3
B25: Day | D25: =SUM(E25:BG25) -> 0
B26: Night | D26: =SUM(E26:BG26) -> 0
A27: 46124 | B27: Day | C27: =SUM(D27:D30) -> 720 | D27: =SUM(E27:BG27) -> 320 | N27: 320 | BH27: =SUM(E27:AC30) -> 720 | BI27: =SUM(E27:BC30) -> 720 | BJ27: AL SUMO | BK27: G.B | BL27: N/A
B28: Night | D28: =SUM(E28:BG28) -> 400 | N28: 400
B29: Night | D29: =SUM(E29:BG29) -> 0
B30: Night | D30: =SUM(E30:BG30) -> 0
A31: 46125 | B31: Day | C31: =SUM(D31:D33) -> 283 | D31: =SUM(E31:BG31) -> 283 | N31: 280 | BE31: 3 | BH31: =SUM(E31:AC33) -> 280 | BI31: =SUM(E31:BC33) -> 280 | BJ31: AL SUMO | BK31: G.B | BL31: N/A
B32: Night | D32: =SUM(E32:BG32) -> 0
B33: Night | D33: =SUM(E33:BG33) -> 0
A34: 46127 | B34: Day | C34: =SUM(D34:D36) -> 594 | D34: =SUM(E34:BG34) -> 171 | H34: 160 | AG34: 1 | BE34: 10 | BH34: =SUM(E34:AC36) -> 576 | BI34: =SUM(E34:BC36) -> 577 | BJ34: 301 | BK34: BROWN | BL34: N/A
B35: Night | D35: =SUM(E35:BG35) -> 423 | H35: 416 | BE35: 7
B36: Night | D36: =SUM(E36:BG36) -> 0
A37: 46128 | B37: Day | C37: =SUM(D37:D40) -> 721 | D37: =SUM(E37:BG37) -> 439 | H37: 432 | AG37: 1 | BE37: 6 | BH37: =SUM(E37:AC40) -> 704 | BI37: =SUM(E37:BC40) -> 705 | BJ37: 301 | BK37: BROWN | BL37: N/A
B38: Night | D38: =SUM(E38:BG38) -> 282 | H38: 272 | BE38: 10
B39: Night | D39: =SUM(E39:BG39) -> 0
B40: Night | D40: =SUM(E40:BG40) -> 0
...

Sheet M-4
A1: 46113
BC2: 1 | BD2: 4 | BE2: 2026
A3: M-4 | E3: Fresh Piece | AA3: Colour Mix Piece | AW3: Rejection Piece
A4: DATE | B4: SHIFT | C4: TOTAL PIECE | E4: Big Chair | F4: Big Maharaja | G4: XUV | H4: Chota Heritage | I4: Small Chair | J4: High Cros | K4: Activa | L4: Inv | M4: EV.Chair | N4: M.P Stool | O4: STOOL CLIPON | P4: Baba Chair | Q4: Jordan Chair | R4: JIO TOP JALI | S4: J.New | T4: Yoddha | U4: Fruit Crate | V4: ALess | W4: D.Leg | X4: C.Table | Y4: Table | Z4: Garden Table | AA4: Big Chair | AB4: Big Maharaja | AC4: XUV | AD4: Chota Heritage | AE4: Small Chair | AF4: High Cros | AG4: Activa | AH4: Inv | AI4: EV.Chair | AJ4: M.P Stool | AK4: STOOL CLIPON | AL4: Baba Chair | AM4: Jordan Chair | AN4: JIO TOP JALI | AO4: J.New | AP4: Yoddha | AQ4: Fruit Crate | AR4: Aless | AS4: D.Leg | AT4: C.Table | AU4: Table | AV4: Garden Table | AW4: Big Chair/Mj/Heritage | AX4: Small Chair/Aless/CH/high cros | AY4: Fruit Crate | AZ4: Table/T.New | BA4: Net Fresh Piece | BB4: Net Usable Prod. | BC4: MODEL | BD4: COLOR | BE4: REMARKS
A5: 46116 | B5: Day | C5: =SUM(D5:D7) -> 733 | D5: =SUM(E5:AZ5) -> 323 | K5: 320 | AX5: 3 | BA5: =SUM(E5:Z7) -> 720 | BB5: =SUM(E5:AV7) -> 725 | BC5: 4003 | BD5: T.W | BH5: S
B6: Night | D6: =SUM(E6:AZ6) -> 410 | K6: 400 | AG6: 5 | AX6: 5
B7: Night | D7: =SUM(E7:AZ7) -> 0
A8: 46117 | B8: Day | C8: =SUM(D8:D11) -> 979 | D8: =SUM(E8:AZ8) -> 472 | K8: =128+336 -> 464 | AG8: 1 | AX8: 7 | BA8: =SUM(E8:Z11) -> 960 | BB8: =SUM(E8:AV11) -> 966 | BC8: 4003 | BD8: T.W | BE8: N/A
B9: Night | D9: =SUM(E9:AZ9) -> 507 | K9: 496 | AG9: 5 | AX9: 6 | BC9: 4001 | BD9: T.W
B10: Night | D10: =SUM(E10:AZ10) -> 0
B11: Night | D11: =SUM(E11:AZ11) -> 0
A12: 46118 | B12: Day | C12: =SUM(D12:D14) -> 1001 | D12: =SUM(E12:AZ12) -> 453 | K12: =80+368 -> 448 | AG12: 2 | AX12: 3 | BA12: =SUM(E12:Z14) -> 992 | BB12: =SUM(E12:AV14) -> 994 | BC12: 4001 | BD12: T.W, G.B
B13: Night | D13: =SUM(E13:AZ13) -> 548 | K13: 544 | AX13: 4
B14: Night | D14: =SUM(E14:AZ14) -> 0
A15: 46119 | B15: Day | C15: =SUM(D15:D18) -> 144 | D15: =SUM(E15:AZ15) -> 144 | K15: 144 | BA15: =SUM(E15:Z18) -> 144 | BB15: =SUM(E15:AV18) -> 144 | BE15: N/A
B16: Night | D16: =SUM(E16:AZ16) -> 0
B17: Night | D17: =SUM(E17:AZ17) -> 0
B18: Night | D18: =SUM(E18:AZ18) -> 0
A19: 46126 | B19: Day | C19: =SUM(D19:D22) -> 374 | D19: =SUM(E19:AZ19) -> 374 | K19: 368 | AX19: 6 | BA19: =SUM(E19:Z22) -> 368 | BB19: =SUM(E19:AV22) -> 368 | BC19: 4003 | BD19: G.B | BE19: N/A
B20: Night | D20: =SUM(E20:AZ20) -> 0
B21: Night | D21: =SUM(E21:AZ21) -> 0
B22: Night | D22: =SUM(E22:AZ22) -> 0
A23: 46127 | B23: Day | C23: =SUM(D23:D26) -> 386 | D23: =SUM(E23:AZ23) -> 386 | K23: 384 | AX23: 2 | BA23: =SUM(E23:Z26) -> 384 | BB23: =SUM(E23:AV26) -> 384 | BC23: 4003 | BD23: G.B | BE23: N/A
B24: Night | D24: =SUM(E24:AZ24) -> 0
B25: Night | D25: =SUM(E25:AZ25) -> 0
B26: Night | D26: =SUM(E26:AZ26) -> 0
A27: 46128 | B27: Day | C27: =SUM(D27:D29) -> 783 | D27: =SUM(E27:AZ27) -> 468 | K27: =128+336 -> 464 | AX27: 4 | BA27: =SUM(E27:Z29) -> 768 | BB27: =SUM(E27:AV29) -> 775 | BC27: 4003 | BD27: G.B , BROWN | BE27: N/A
B28: Night | D28: =SUM(E28:AZ28) -> 315 | K28: =256+48 -> 304 | AG28: 7 | AX28: 4
B29: Night | D29: =SUM(E29:AZ29) -> 0
A30: 46129 | B30: Day | C30: =SUM(D30:D32) -> 993 | D30: =SUM(E30:AZ30) -> 504 | K30: 496 | AG30: 3 | AX30: 5 | BA30: =SUM(E30:Z32) -> 976 | BB30: =SUM(E30:AV32) -> 984 | BC30: 4003 | BD30: A.G | BE30: N/A
B31: Night | D31: =SUM(E31:AZ31) -> 489 | K31: =112+368 -> 480 | AG31: 5 | AX31: =1+3 -> 4
B32: Night | D32: =SUM(E32:AZ32) -> 0
A33: 46130 | B33: Day | C33: =SUM(D33:D36) -> 581 | D33: =SUM(E33:AZ33) -> 581 | K33: =512+64 -> 576 | AX33: =4+1 -> 5 | BA33: =SUM(E33:Z36) -> 576 | BB33: =SUM(E33:AV36) -> 576 | BC33: 4003 | BD33: BROWN | BE33: N/A
B34: Day | D34: =SUM(E34:AZ34) -> 0
B35: Night | D35: =SUM(E35:AZ35) -> 0
B36: Night | D36: =SUM(E36:AZ36) -> 0
A37: 46131 | B37: Day | C37: =SUM(D37:D39) -> 500 | D37: =SUM(E37:AZ37) -> 500 | K37: 496 | AX37: 4 | BA37: =SUM(E37:Z39) -> 496 | BB37: =SUM(E37:AV39) -> 496 | BC37: 4002 | BD37: BROWN | BE37: N/A
B38: Night | D38: =SUM(E38:AZ38) -> 0
B39: Night | D39: =SUM(E39:AZ39) -> 0
A40: 46132 | B40: Day | C40: =SUM(D40:D42) -> 478 | D40: =SUM(E40:AZ40) -> 478 | K40: =192+272 -> 464 | AX40: =5+9 -> 14 | BA40: =SUM(E40:Z42) -> 464 | BB40: =SUM(E40:AV42) -> 464 | BC40: 4002 | BD40: BROWN , G.B | BE40: N/A
...

Sheet M-5
A1: 46113
BK2: 1 | BL2: 4 | BM2: 2026
A3: M-5 | E3: Fresh Piece | AE3: Colour Mix Piece | BE3: Rejection Piece
A4: DATE | B4: SHIFT | C4: TOTAL PIECE | E4: Big Chair | F4: Big Maharaja | G4: XUV | H4: Chota Heritage | I4: Innova | J4: CLIPON STOOL | K4: Activa | L4: High Cross | M4: Yoddha | N4: Wab Chair | O4: Stool | P4: Jordan Chair/ Clip | Q4: Baby Chair | R4: Baba Chair | S4: Heritage | T4: J.New | U4: Fridge Stand | V4: M.P.Stool | W4: Fruit Crate | X4: ALess | Y4: Small Chair | Z4: D.Table | AA4: D.Leg Cn | AB4: C.Table | AC4: Table | AD4: Garden Table | AE4: Big Chair | AF4: Big Maharaja | AG4: XUV | AH4: Chota Heritage | AI4: Innova | AJ4: CLIPON STOOL | AK4: Activa | AL4: Yodha | AM4: Wab Chair | AN4: Stool | AO4: Baby Chair | AP4: Baba Chair | AQ4: Jordan Chair/ Clip | AR4: Heritage | AS4: High Cross | AT4: J.New | AU4: Fridge Stand | AV4: M.P.Stool | AW4: Fruit Crate | AX4: Small Chair | AY4: D.Table | AZ4: D.Leg Cn | BA4: Aless | BB4: C.Table | BC4: Table | BD4: Garden Table | BE4: Big Chair/Mj/Heritage | BF4: Small Chair/Aless/CH/Act/Yodh/ Wab Char | BG4: Fridge Stand/Stool | BH4: Table/T.New | BI4: Net Fresh Piece | BJ4: Net Usable Prod. | BK4: MODEL | BL4: COLOR | BM4: REMARKS
A5: 46121 | B5: Day | C5: =SUM(D5:D7) -> 700 | D5: =SUM(E5:BH5) -> 189 | AC5: 180 | BC5: 2 | BH5: 7 | BI5: =SUM(E5:AD7) -> 684 | BJ5: =SUM(E5:BD7) -> 686 | BK5: T.T | BL5: BROWN | BM5: N/A
B6: Night | D6: =SUM(E6:BH6) -> 511 | AC6: 504 | BH6: 7
B7: Night | D7: =SUM(E7:BH7) -> 0
A8: 46122 | B8: Day | C8: =SUM(D8:D11) -> 1044 | D8: =SUM(E8:BH8) -> 538 | AC8: 516 | BC8: 3 | BH8: 19 | BI8: =SUM(E8:AD11) -> 1020 | BJ8: =SUM(E8:BD11) -> 1023 | BK8: T.T | BL8: BROWN | BM8: N/A
B9: Night | D9: =SUM(E9:BH9) -> 506 | AC9: 504 | BH9: 2
B10: Night | D10: =SUM(E10:BH10) -> 0
B11: Night | D11: =SUM(E11:BH11) -> 0
A12: 46123 | B12: Day | C12: =SUM(D12:D15) -> 812 | D12: =SUM(E12:BH12) -> 308 | AC12: =120+180 -> 300 | BC12: 7 | BH12: 1 | BI12: =SUM(E12:AD15) -> 804 | BJ12: =SUM(E12:BD15) -> 811 | BK12: T.T | BL12: BROWN, A.G | BM12: N/A
B13: Night | D13: =SUM(E13:BH13) -> 504 | AC13: 504
B14: Night | D14: =SUM(E14:BH14) -> 0
B15: Night | D15: =SUM(E15:BH15) -> 0
A16: 46124 | B16: Day | C16: =SUM(D16:D18) -> 883 | D16: =SUM(E16:BH16) -> 376 | AC16: 372 | BC16: 4 | BI16: =SUM(E16:AD18) -> 864 | BJ16: =SUM(E16:BD18) -> 879 | BK16: T.T | BL16: A.G | BM16: N/A
B17: Night | D17: =SUM(E17:BH17) -> 507 | AC17: =156+336 -> 492 | BC17: =3+8 -> 11 | BH17: 4
B18: Night | D18: =SUM(E18:BH18) -> 0
A19: 46125 | B19: Day | C19: =SUM(D19:D22) -> 1071 | D19: =SUM(E19:BH19) -> 573 | AC19: =528+36 -> 564 | BC19: 2 | BH19: =6+1 -> 7 | BI19: =SUM(E19:AD22) -> 1044 | BJ19: =SUM(E19:BD22) -> 1046 | BK19: T.T | BL19: R.W , S.B
B20: Night | D20: =SUM(E20:BH20) -> 498 | AC20: 480 | BH20: 18
B21: Night | D21: =SUM(E21:BH21) -> 0
B22: Night | D22: =SUM(E22:BH22) -> 0
A23: 46126 | B23: Day | C23: =SUM(D23:D25) -> 180 | D23: =SUM(E23:BH23) -> 180 | AC23: 168 | BH23: 12 | BI23: =SUM(E23:AD25) -> 168 | BJ23: =SUM(E23:BD25) -> 168 | BK23: T.T | BL23: S.B | BM23: N/A
B24: Night | D24: =SUM(E24:BH24) -> 0
B25: Night | D25: =SUM(E25:BH25) -> 0
A26: 46131 | B26: Day | C26: =SUM(D26:D29) -> 359 | D26: =SUM(E26:BH26) -> 359 | S26: 352 | AR26: 2 | BE26: 5 | BI26: =SUM(E26:AD29) -> 352 | BJ26: =SUM(E26:BD29) -> 354 | BK26: 6003 | BL26: G.B | BM26: N/A
B27: Night | D27: =SUM(E27:BH27) -> 0 | BN27: WAB SAMPLEE
B28: Night | D28: =SUM(E28:BH28) -> 0
B29: Night | D29: =SUM(E29:BH29) -> 0
A30: 46132 | B30: Day | C30: =SUM(D30:D33) -> 474 | D30: =SUM(E30:BH30) -> 474 | S30: 464 | BE30: 10 | BI30: =SUM(E30:AD33) -> 464 | BJ30: =SUM(E30:BD33) -> 464 | BK30: 6003 | BL30: G.B | BM30: N/A
B31: Night | D31: =SUM(E31:BH31) -> 0
B32: Night | D32: =SUM(E32:BH32) -> 0
B33: Night | D33: =SUM(E33:BH33) -> 0
A34: 46133 | B34: Day | C34: =SUM(D34:D37) -> 487 | D34: =SUM(E34:BH34) -> 487 | S34: =112+368 -> 480 | AR34: 2 | BE34: =3+2 -> 5 | BI34: =SUM(E34:AD37) -> 480 | BJ34: =SUM(E34:BD37) -> 482 | BK34: 6003 | BL34: G.B | BM34: N/A
B35: Night | D35: =SUM(E35:BH35) -> 0 | BK35: 6002 | BL35: BROWN
B36: Night | D36: =SUM(E36:BH36) -> 0
B37: Night | D37: =SUM(E37:BH37) -> 0
A38: 46134 | B38: Day | C38: =SUM(D38:D40) -> 498 | D38: =SUM(E38:BH38) -> 498 | S38: 496 | BE38: 2 | BI38: =SUM(E38:AD40) -> 496 | BJ38: =SUM(E38:BD40) -> 496 | BK38: 6002 | BL38: BROWN | BM38: N/A
B39: Night | D39: =SUM(E39:BH39) -> 0
B40: Night | D40: =SUM(E40:BH40) -> 0
...

Sheet M-6
A1: 46113
BN2: 1 | BO2: 4 | BP2: 2026
A3: M-6 | E3: Fresh Piece | AF3: Colour Mix Piece | BH3: Rejection Piece
A4: DATE | B4: SHIFT | C4: TOTAL PIECE | E4: Big Chair | F4: Big Maharaja | G4: XUV | H4: Chota Heritage | I4: Yoddhaa | J4: Innova | K4: Activa | L4: Jordan Chair | M4: Stool | N4: Stool ClipOn | O4: Sumo | P4: Baby Chair | Q4: Baba Chair | R4: Heritage | S4: Jarden Chair | T4: Fridge Stand | U4: EV.Chair | V4: Small Chair | W4: M.P.Stool | X4: Fruit Crate | Y4: ALess | AA4: D.Table | AB4: D.Leg Cn | AC4: C.Table | AD4: Table | AE4: Garden Table | AF4: Big Chair | AG4: Big Maharaja | AH4: XUV | AI4: Chota Heritage | AK4: Innova | AL4: Activa | AM4: Stool | AN4: Stool ClipON | AO4: Baby Chair | AP4: Baba Chair | AQ4: Jordan Chair/ Clip | AR4: Heritage | AS4: Jordan Chair | AT4: Jarden Chair | AU4: Fridge Stand | AV4: EVChair | AW4: Yoddha | AX4: Small Chair | AY4: M.P.Stool | AZ4: Fruit Crate | BA4: Small Chair | BB4: D.Table | BC4: D.Leg Cn | BD4: Aless | BE4: C.Table | BF4: Table | BG4: Garden Table | BH4: Big Chair/Mj/Heritage | BI4: Small Chair/Aless/CH/Act/J.D/SIGM/EV | BJ4: Fridge Stand/Stool | BK4: Table/T.New | BL4: Net Fresh Piece | BM4: Net Usable Prod. | BN4: MODEL | BO4: COLOR | BP4: REMARKS
A5: 46116 | B5: Day | C5: =SUM(D5:D8) -> 281 | D5: =SUM(E5:BK5) -> 281 | I5: 276 | BI5: 5 | BL5: =SUM(E5:AE8) -> 276 | BM5: =SUM(E5:BG8) -> 276 | BN5: 502 | BO5: G.B | BP5: N/A
B6: Night | D6: =SUM(E6:BK6) -> 0
B7: Night | D7: =SUM(E7:BK7) -> 0
B8: Night | D8: =SUM(E8:BK8) -> 0
A9: 46119 | B9: Day | C9: =SUM(D9:D12) -> 544 | D9: =SUM(E9:BK9) -> 88 | I9: 84 | AW9: 1 | BI9: 3 | BL9: =SUM(E9:AE12) -> 540 | BM9: =SUM(E9:BG12) -> 541 | BN9: 502 | BO9: BROWN | BP9: N/A
B10: Night | D10: =SUM(E10:BK10) -> 456 | I10: 456
B11: Night | D11: =SUM(E11:BK11) -> 0
B12: Night | D12: =SUM(E12:BK12) -> 0
A13: 46120 | B13: Day | C13: =SUM(D13:D16) -> 868 | D13: =SUM(E13:BK13) -> 458 | I13: 456 | BI13: 2 | BL13: =SUM(E13:AE16) -> 864 | BM13: =SUM(E13:BG16) -> 864 | BN13: 502 | BO13: BROWN | BP13: N/A
B14: Day | D14: =SUM(E14:BK14) -> 410 | I14: 408 | BI14: 2
B15: Night | D15: =SUM(E15:BK15) -> 0
B16: Night | D16: =SUM(E16:BK16) -> 0
A17: 46121 | B17: Day | C17: =SUM(D17:D19) -> 285 | D17: =SUM(E17:BK17) -> 285 | I17: =204+72 -> 276 | AW17: 4 | BI17: 5 | BL17: =SUM(E17:AE19) -> 276 | BM17: =SUM(E17:BG19) -> 280 | BN17: 502 | BO17: BROWN , T.W | BP17: N/A
B18: Night | D18: =SUM(E18:BK18) -> 0
B19: Night | D19: =SUM(E19:BK19) -> 0
A20: 46123 | B20: Day | C20: =SUM(D20:D23) -> 218 | D20: =SUM(E20:BK20) -> 218 | I20: =24+192 -> 216 | BI20: 2 | BL20: =SUM(E20:AE23) -> 216 | BM20: =SUM(E20:BG23) -> 216 | BN20: 502 | BO20: T.W , BROWN
B21: Night | D21: =SUM(E21:BK21) -> 0
B22: Night | D22: =SUM(E22:BK22) -> 0
B23: Night | D23: =SUM(E23:BK23) -> 0
A24: 46124 | B24: Day | C24: =SUM(D24:D26) -> 340 | D24: =SUM(E24:BK24) -> 340 | I24: =84+252 -> 336 | AW24: 1 | BI24: 3 | BL24: =SUM(E24:AE26) -> 336 | BM24: =SUM(E24:BG26) -> 337 | BN24: 502 | BO24: BROWN , G.B | BP24: N/A
B25: Day | D25: =SUM(E25:BK25) -> 0
B26: Night | D26: =SUM(E26:BK26) -> 0
A27: 46125 | B27: Day | C27: =SUM(D27:D29) -> 495 | D27: =SUM(E27:BK27) -> 495 | I27: 492 | BI27: 3 | BL27: =SUM(E27:AE29) -> 492 | BM27: =SUM(E27:BG29) -> 492 | BN27: 502 | BO27: G.B | BP27: N/A
B28: Night | D28: =SUM(E28:BK28) -> 0
B29: Night | D29: =SUM(E29:BK29) -> 0
A30: 46126 | B30: Day | C30: =SUM(D30:D34) -> 367 | D30: =SUM(E30:BK30) -> 367 | I30: 360 | BI30: 7 | BL30: =SUM(E30:AE34) -> 360 | BM30: =SUM(E30:BG34) -> 360 | BN30: 502 | BO30: G.B | BP30: N/A
B31: Night | D31: =SUM(E31:BK31) -> 0
B32: Night | D32: =SUM(E32:BK32) -> 0
B33: Night | D33: =SUM(E33:BK33) -> 0
B34: Day | D34: =SUM(E34:BK34) -> 0
A35: 46127 | B35: Day | C35: =SUM(D35:D38) -> 211 | D35: =SUM(E35:BK35) -> 211 | I35: 204 | BI35: 7 | BL35: =SUM(E35:AE38) -> 204 | BM35: =SUM(E35:BG38) -> 204 | BN35: 502 | BO35: G.B | BP35: N/A
B36: Night | D36: =SUM(E36:BK36) -> 0
B37: Night | D37: =SUM(E37:BK37) -> 0
B38: Night | D38: =SUM(E38:BK38) -> 0
A39: 46128 | B39: Day | C39: =SUM(D39:D42) -> 206 | D39: =SUM(E39:BK39) -> 206 | I39: 198 | BI39: 8 | BL39: =SUM(E39:AE42) -> 198 | BM39: =SUM(E39:BG42) -> 198 | BN39: 502 | BO39: G.B | BP39: N/A
B40: Night | D40: =SUM(E40:BK40) -> 0
...

Sheet M-7
A1: 46113
BN2: 1 | BO2: 4 | BP2: 26
A3: M-7 | E3: Fresh Piece | AF3: Colour Mix Piece | BH3: Rejection Piece
A4: DATE | B4: SHIFT | C4: TOTAL PIECE | E4: Big Chair | F4: Big Maharaja | G4: XUV | H4: Chota Heritage | I4: Aless | J4: Innova | K4: Activa | L4: Jordan Chair | M4: Stool | N4: Stool ClipOn | O4: SUMO | P4: Baby Chair | Q4: Baba Chair | R4: HIGH CROSS | S4: J.New | T4: Fridge Stand | U4: EV.Chair | V4: Small Chair | W4: M.P.Stool | X4: Fruit Crate | Z4: JIO LEG | AA4: D.Table | AB4: D.Leg Cn | AC4: C.Table | AD4: Table | AE4: Garden Table | AF4: Big Chair | AG4: Big Maharaja | AH4: XUV | AI4: Chota Heritage | AJ4: JIO LEG | AK4: Innova | AL4: Activa | AM4: Stool | AN4: Stool ClipON | AO4: Baby Chair | AP4: Baba Chair | AQ4: SUMO | AR4: HIGH CROSS | AS4: Jordan Chair | AT4: J.New | AU4: Fridge Stand | AV4: EVChair | AW4: Aless | AX4: Small Chair | AY4: M.P.Stool | AZ4: Fruit Crate | BA4: Small Chair | BB4: D.Table | BC4: D.Leg Cn | BD4: High Cross | BE4: C.Table | BF4: Table | BG4: Garden Table | BH4: Big Chair/Mj/Heritage | BI4: Small Chair/Aless/CH/Act/J.D/SIGM/EV | BJ4: Fridge Stand/Stool | BK4: Table/T.New | BL4: Net Fresh Piece | BM4: Net Usable Prod. | BN4: MODEL | BO4: COLOR | BP4: REMARKS
A5: 46130 | B5: Day | C5: =SUM(D5:D8) -> 1301 | D5: =SUM(E5:BK5) -> 579 | I5: 560 | AW5: 7 | BI5: 12 | BL5: =SUM(E5:AE8) -> 1280 | BM5: =SUM(E5:BG8) -> 1289 | BN5: 101 | BO5: ORANGE | BP5: N/A
B6: Night | D6: =SUM(E6:BK6) -> 722 | I6: =440+280 -> 720 | AW6: 2
B7: Night | D7: =SUM(E7:BK7) -> 0
B8: Night | D8: =SUM(E8:BK8) -> 0
A9: 46131 | B9: Day | C9: =SUM(D9:D12) -> 1403 | D9: =SUM(E9:BK9) -> 680 | I9: 680 | BL9: =SUM(E9:AE12) -> 1400 | BM9: =SUM(E9:BG12) -> 1400 | BN9: 101 | BO9: RED 1 | BP9: N/A
B10: Night | D10: =SUM(E10:BK10) -> 723 | I10: 720 | BI10: 3
B11: Night | D11: =SUM(E11:BK11) -> 0
B12: Night | D12: =SUM(E12:BK12) -> 0
A13: 46132 | B13: Day | C13: =SUM(D13:D16) -> 1224 | D13: =SUM(E13:BK13) -> 720 | I13: 720 | BL13: =SUM(E13:AE16) -> 1220 | BM13: =SUM(E13:BG16) -> 1220 | BN13: 101 | BO13: RED 1 | BP13: N/A
B14: Night | D14: =SUM(E14:BK14) -> 504 | I14: 500 | BI14: 4
B15: Night | D15: =SUM(E15:BK15) -> 0
B16: Night | D16: =SUM(E16:BK16) -> 0
A17: 46133 | B17: Day | C17: =SUM(D17:D19) -> 702 | D17: =SUM(E17:BK17) -> 702 | I17: 700 | AW17: 2 | BL17: =SUM(E17:AE19) -> 700 | BM17: =SUM(E17:BG19) -> 702 | BN17: 101 | BO17: RED 1 | BP17: N/A
B18: Day | D18: =SUM(E18:BK18) -> 0
B19: Night | D19: =SUM(E19:BK19) -> 0
A20: 46134 | B20: Day | C20: =SUM(D20:D23) -> 1011 | D20: =SUM(E20:BK20) -> 624 | I20: 620 | BI20: 4 | BL20: =SUM(E20:AE23) -> 1000 | BM20: =SUM(E20:BG23) -> 1000 | BN20: 101 | BO20: RED 1 , BROWN
B21: Night | D21: =SUM(E21:BK21) -> 387 | I21: =80+300 -> 380 | BI21: =2+5 -> 7
B22: Night | D22: =SUM(E22:BK22) -> 0
B23: Night | D23: =SUM(E23:BK23) -> 0
A24: 46135 | B24: Day | C24: =SUM(D24:D26) -> 403 | D24: =SUM(E24:BK24) -> 403 | I24: 400 | BI24: 3 | BL24: =SUM(E24:AE26) -> 400 | BM24: =SUM(E24:BG26) -> 400 | BN24: 103 | BO24: BROWN | BP24: N/A
B25: Night | D25: =SUM(E25:BK25) -> 0
B26: Night | D26: =SUM(E26:BK26) -> 0
A27: 46136 | B27: Day | C27: =SUM(D27:D29) -> 602 | D27: =SUM(E27:BK27) -> 602 | I27: 600 | BI27: 2 | BL27: =SUM(E27:AE29) -> 600 | BM27: =SUM(E27:BG29) -> 600 | BN27: 103 | BO27: BROWN | BP27: N/A
B28: Night | D28: =SUM(E28:BK28) -> 0
B29: Night | D29: =SUM(E29:BK29) -> 0
A30: 46137 | B30: Day | C30: =SUM(D30:D34) -> 601 | D30: =SUM(E30:BK30) -> 601 | I30: 600 | BI30: 1 | BL30: =SUM(E30:AE34) -> 600 | BM30: =SUM(E30:BG34) -> 600 | BN30: 103 | BO30: BROWN | BP30: N/A
B31: Night | D31: =SUM(E31:BK31) -> 0
B32: Night | D32: =SUM(E32:BK32) -> 0
B33: Night | D33: =SUM(E33:BK33) -> 0
B34: Day
A35: 46138 | B35: Day | C35: =SUM(D35:D38) -> 585 | D35: =SUM(E35:BK35) -> 585 | I35: 580 | BI35: 5 | BL35: =SUM(E35:AE38) -> 580 | BM35: =SUM(E35:BG38) -> 580 | BN35: 103 | BO35: BROWN | BP35: N/A
B36: Night | D36: =SUM(E36:BK36) -> 0
B37: Night | D37: =SUM(E37:BK37) -> 0
B38: Night | D38: =SUM(E38:BK38) -> 0
A39: 46139 | B39: Day | C39: =SUM(D39:D42) -> 583 | D39: =SUM(E39:BK39) -> 583 | I39: 580 | BI39: 3 | BL39: =SUM(E39:AE42) -> 580 | BM39: =SUM(E39:BG42) -> 580 | BN39: 103 | BO39: BROWN | BP39: N/A
B40: Night | D40: =SUM(E40:BK40) -> 0
...

Sheet BIG CHAIR
A1: Finished Production of Big Chairs - Period on Dated | H1: 1 | I1: 4 | J1: 2026
F2: 2001(New) | O2: 5001 (Maharaja) | X2: 5002 (Maharaja) - Gold | AG2: 5003 (Flower) | AP2: 6001 (Goli) | AY2: 6002 (Chattai) | BH2: 6003 (Patti) | BQ2: 2002 | BZ2: 10001 New (Goli)
A3: Production M-1 | B3: Name | C3: B.No. | D3: Date | F3: S-W | G3: G.B | H3: B.Silver | I3: A.Gold | J3: M.Bz | K3: P.Silver | L3: R-W | M3: Brown | O3: S-W | P3: C-W | Q3: B-Silver | R3: KR | S3: M.Bz | T3: BCM | U3: R-W | V3: Mix | X3: A.Gold | Y3: White | Z3: Karara | AA3: P-Silver | AB3: M.Bz | AC3: Blue,5003 | AD3: Red F | AE3: 5003, Orange | AG3: P.Pink | AH3: P.Green | AI3: R-W | AJ3: M.Bz | AK3: B-Silver | AL3: Brown | AM3: S.Wood | AN3: A.Gold | AP3: P.Green | AQ3: Blue | AR3: P.White | AS3: Orange | AT3: Red First | AU3: P.Pink | AV3: Brown First | AW3: M.B. | AY3: P-Silver | AZ3: S-Wood | BA3: A.Gold | BB3: Black | BC3: M.Bz | BD3: Brown | BE3: White | BF3: B.Gold | BH3: S-W | BI3: G.Black | BJ3: T-Wood | BK3: S-Black | BL3: M.Bz | BM3: A.G | BN3: R-W | BO3: Gold | BQ3: Red First | BR3: A.G | BS3: Orange | BT3: Brown | BU3: P.Green | BV3: G . Black | BW3: Yellow | BX3: Blue | BZ3: Mix | CA3: YELLOW | CB3: S .B 2002 | CC3: 2001OK | CD3: T.W 2002 | CE3: M.B 1 | CF3: R-W | CG3: S-Wood | CI3: Fresh | CJ3: C-Mix | CL3: Total | CM3: G.Rejn | CN3: G.Total
A4: Opening Stock as on | B4: Pushpanjli | F4: =61*16 -> 976 | H4: =79*16 -> 1264 | J4: =48*16 -> 768 | L4: =57*16 -> 912 | Y4: =8*16 -> 128 | AD4: =2*16 -> 32 | AE4: =17*16 -> 272 | AI4: =44*16 -> 704 | AK4: =91*16 -> 1456 | AM4: =115*16 -> 1840 | AP4: =2*16 -> 32 | AQ4: =23*16 -> 368 | AR4: =3*16 -> 48 | BA4: =110*16 -> 1760 | BC4: =39*16 -> 624 | BD4: =191*16 -> 3056 | BI4: =61*16 -> 976 | BJ4: =83*16 -> 1328 | BK4: =29*16 -> 464 | BN4: =10*16 -> 160 | BQ4: =1*16 -> 16 | BV4: =35*16 -> 560 | BX4: =29*16 -> 464 | BZ4: =73*16 -> 1168 | CD4: =25*16 -> 400 | CI4: =SUM(F4:CG4) -> 19776 | CL4: =CI4+CJ4 -> 19776 | CN4: =CL4+CM4 -> 19776
A5: Production add M- 1 | CI5: =SUM(F5:CG5) -> 0 | CL5: =CI5+CJ5 -> 0 | CN5: =CL5+CM5 -> 0
A6: Production add M- 1 | CI6: =SUM(F6:CG6) -> 0 | CL6: =CI6+CJ6 -> 0 | CN6: =CL6+CM6 -> 0
A7: Production add M- 1 | CI7: =SUM(F7:CG7) -> 0 | CL7: =CI7+CJ7 -> 0 | CN7: =CL7+CM7 -> 0
A8: Production add M- 1 | CI8: =SUM(F8:CG8) -> 0 | CL8: =CI8+CJ8 -> 0 | CN8: =CL8+CM8 -> 0
A9: Production add M- 1 | CI9: =SUM(F9:CG9) -> 0 | CL9: =CI9+CJ9 -> 0 | CN9: =CL9+CM9 -> 0
A10: Production add M- 1 | CI10: =SUM(F10:CG10) -> 0 | CL10: =CI10+CJ10 -> 0 | CN10: =CL10+CM10 -> 0
A11: Production add M- 1 | CI11: =SUM(F11:CG11) -> 0 | CL11: =CI11+CJ11 -> 0 | CN11: =CL11+CM11 -> 0
A12: Production add M- 1 | CI12: =SUM(F12:CG12) -> 0 | CL12: =CI12+CJ12 -> 0 | CN12: =CL12+CM12 -> 0
A13: Production add M- 1 | CI13: =SUM(F13:CG13) -> 0 | CL13: =CI13+CJ13 -> 0 | CN13: =CL13+CM13 -> 0
A14: Production add M- 1 | CI14: =SUM(F14:CG14) -> 0 | CL14: =CI14+CJ14 -> 0 | CN14: =CL14+CM14 -> 0
A15: Production add M- 1 | CI15: =SUM(F15:CG15) -> 0 | CL15: =CI15+CJ15 -> 0 | CN15: =CL15+CM15 -> 0
A16: Production add M- 1 | CI16: =SUM(F16:CG16) -> 0 | CL16: =CI16+CJ16 -> 0 | CN16: =CL16+CM16 -> 0
... A21: Production add M- 1 | CI21: =SUM(F21:CG21) -> 0 | CL21: =CI21+CJ21 -> 0 | CN21: =CL21+CM21 -> 0
A22: Production add M- 1 | CI22: =SUM(F22:CG22) -> 0 | CL22: =CI22+CJ22 -> 0 | CN22: =CL22+CM22 -> 0 | CO22: Small | CP22: Table | CQ22: Production
A23: Production add M- 1 | CI23: =SUM(F23:CG23) -> 0 | CL23: =CI23+CJ23 -> 0 | CN23: =CL23+CM23 -> 0
A24: Production add M- 1 | CI24: =SUM(F24:CG24) -> 0 | CL24: =CI24+CJ24 -> 0 | CN24: =CL24+CM24 -> 0
A25: Production add M- 1 | CI25: =SUM(F25:CG25) -> 0 | CL25: =CI25+CJ25 -> 0 | CN25: =CL25+CM25 -> 0
A26: Production add M- 1 | CI26: =SUM(F26:CG26) -> 0 | CL26: =CI26+CJ26 -> 0 | CN26: =CL26+CM26 -> 0
A27: Production add M- 1 | CI27: =SUM(F27:CG27) -> 0 | CL27: =CI27+CJ27 -> 0 | CN27: =CL27+CM27 -> 0
A28: Production add M- 1 | CI28: =SUM(F28:CG28) -> 0 | CL28: =CI28+CJ28 -> 0 | CN28: =CL28+CM28 -> 0
A29: Production add M- 1 | CI29: =SUM(F29:CG29) -> 0 | CL29: =CI29+CJ29 -> 0 | CN29: =CL29+CM29 -> 0
A30: Production add M- 1 | CI30: =SUM(F30:CG30) -> 0 | CL30: =CI30+CJ30 -> 0 | CN30: =CL30+CM30 -> 0 | CO30: ='Jordan Chair'!AH38 -> 627 | CP30: ='Tea Table'!X29 -> 0 | CQ30: =CL36+CO30+CP30 -> 627
A31: Production add M- 1 | CI31: =SUM(F31:CG31) -> 0 | CL31: =CI31+CJ31 -> 0 | CN31: =CL31+CM31 -> 0
A32: Production add M- 1 | CI32: =SUM(F32:CG32) -> 0 | CL32: =CI32+CJ32 -> 0 | CN32: =CL32+CM32 -> 0
A33: Production add M- 1 | CI33: =SUM(F33:CG33) -> 0 | CL33: =CI33+CJ33 -> 0 | CN33: =CL33+CM33 -> 0
A34: Production add M- 1 | CI34: =SUM(F34:CG34) -> 0 | CL34: =CI34+CJ34 -> 0 | CN34: =CL34+CM34 -> 0
CI35: =BB35+BC35+BD35 -> 0 | CL35: =CI35+CJ35 -> 0 | CN35: =CL35+CM35 -> 0
A36: Production Machine - 1 | F36: =SUM(F5:F35) -> 0 | G36: =SUM(G5:G35) -> 0 | H36: =SUM(H5:H35) -> 0 | I36: =SUM(I5:I35) -> 0 | J36: =SUM(J5:J35) -> 0 | K36: =SUM(K5:K35) -> 0 | L36: =SUM(L5:L35) -> 0 | M36: =SUM(M5:M35) -> 0 | ... CN36: =SUM(CN5:CN35) -> 0
F38: 2001(Flower) | O38: 5001 (Maharaja) | X38: 5002 (Maharaja) | AG38: =AG2 -> 5003 (Flower) | AP38: =AP2 -> 6001 (Goli) | AY38: =AY2 -> 6002 (Chattai) | BH38: =BH2 -> 6003 (Patti) | BQ38: =BQ2 -> 2002 | BZ38: 10001 (Goli)/ Red 1001
A39: Production M-2 | B39: Name | C39: B.No. | D39: Date | F39: S-W | G39: G.B | H39: B.Silver | I39: A.Gold | J39: M.Bz | K39: P.Silver | L39: R-W | M39: Brown | O39: S-W | P39: C-W | Q39: Silver | R39: KR | S39: M.Bz | T39: BCM | U39: R-W | V39: Red | X39: A.Gold | Y39: C-W | Z39: Karara | AA39: P-Silver | AB39: M.Bz | AC39: Blue,5003 | AD39: R-W | AE39: 5003, Orange | AG39: P.Pink | AH39: P.Green | AI39: R-W | AJ39: M.Bz | AK39: B-Silver | AL39: Brown | AM39: S.Wood | AP39: P.Green | AQ39: M.Pink | AR39: P.White | AS39: M.B | AT39: Red First | AU39: P.Pink | AV39: Brown First | AW39: M.B. | AY39: P-Silver | AZ39: S-Wood | BA39: A.Gold | BB39: Black | BC39: M.Bz | BD39: Brown | BE39: White | BF39: Mix | BH39: S-W | BI39: B-Black | BJ39: T-Wood | BK39: S-Black | BL39: M.Bz | BM39: OK | BN39: R-W | BO39: Gold | BQ39: S-W | BR39: A.G | BS39: B.Silver | BT39: Brown | BU39: M.Bz | BV39: B.G | BW39: R-W | BX39: Red | BZ39: Mix | CA39: C-W | CB39: Silver black | CC39: 2001OK | CD39: M.Bz | CE39: Brown | CF39: R-W | CG39: S-Wood | CI39: Fresh | CJ39: C-Mix | CL39: Total | CM39: G.Rejn | CN39: G.Total
A40: Production add M- 2 | B40: Pushpanjli | D40: 46126 | BZ40: =26*16 -> 416 | CI40: =SUM(F40:CG40) -> 416 | CL40: =CI40+CJ40 -> 416 | CM40: 17 | CN40: =CL40+CM40 -> 433
A41: Production add M- 2 | B41: Pushpanjli | D41: 46127 | BZ41: =20*16+28*16 -> 768 | CI41: =SUM(F41:CG41) -> 768 | CL41: =CI41+CJ41 -> 768 | CM41: =16+25 -> 41 | CN41: =CL41+CM41 -> 809
A42: Production add M- 2 | B42: Pushpanjli | D42: 46128 | BZ42: =33*16+22*16 -> 880 | CI42: =SUM(F42:CG42) -> 880 | CL42: =CI42+CJ42 -> 880 | CM42: =11+30 -> 41 | CN42: =CL42+CM42 -> 921 | CO42: Small
A43: Production add M- 2 | B43: Pushpanjli | D43: 46129 | BZ43: =35*16+23*16 -> 928 | CI43: =SUM(F43:CG43) -> 928 | CL43: =CI43+CJ43 -> 928 | CM43: =3+12 -> 15 | CN43: =CL43+CM43 -> 943
A44: Production add M- 2 | B44: Pushpanjli | D44: 46130 | BZ44: =34*16+35*16 -> 1104 | CI44: =SUM(F44:CG44) -> 1104 | CL44: =CI44+CJ44 -> 1104 | CM44: 1 | CN44: =CL44+CM44 -> 1105
A45: Production add M- 2 | B45: Pushpanjli | D45: 46131 | BZ45: =32*16+29*16 -> 976 | CI45: =SUM(F45:CG45) -> 976 | CL45: =CI45+CJ45 -> 976 | CM45: =20+6 -> 26 | CN45: =CL45+CM45 -> 1002
...

Sheet Sumo
A1: Finished Production of Table - Period on Dated | O1: 1 | P1: 4 | Q1: 2026
E2: Sumo - 301
A3: Production M-1 | B3: Name | C3: B.No. | D3: Date | E3: S-W | F3: Coloured | G3: Red | H3: P-Pink | I3: B. Gold | J3: Orange | K3: P-White | L3: Silver.B | M3: P. Silver | N3: A.Gold | O3: P.Green | P3: M.Bz | Q3: Black | R3: R-W | S3: Brown | U3: Fresh | V3: C-Mix | X3: Total | Y3: G.Rejn | Z3: G.Total
A4: Opening Stock as on | B4: Pushpanjli | N4: =13*16 -> 208 | P4: =18*16 -> 288 | U4: =SUM(E4:S4) -> 496 | X4: =U4+V4 -> 496 | Z4: =X4+Y4 -> 496
A5: Production add M- 1 | U5: =SUM(E5:S5) -> 0 | X5: =U5+V5 -> 0 | Z5: =X5+Y5 -> 0
A6: Production add M- 1 | U6: =SUM(E6:S6) -> 0 | X6: =U6+V6 -> 0 | Z6: =X6+Y6 -> 0
A7: Production add M- 1 | U7: =SUM(E7:S7) -> 0 | X7: =U7+V7 -> 0 | Z7: =X7+Y7 -> 0
A8: Production add M- 1 | U8: =SUM(E8:S8) -> 0 | X8: =U8+V8 -> 0 | Z8: =X8+Y8 -> 0
A9: Production add M- 1 | U9: =SUM(E9:S9) -> 0 | X9: =U9+V9 -> 0 | Z9: =X9+Y9 -> 0
A10: Production add M- 1 | U10: =SUM(E10:S10) -> 0 | X10: =U10+V10 -> 0 | Z10: =X10+Y10 -> 0
A11: Production add M- 1 | U11: =SUM(E11:S11) -> 0 | X11: =U11+V11 -> 0 | Z11: =X11+Y11 -> 0
A12: Production add M- 1 | U12: =SUM(E12:S12) -> 0 | X12: =U12+V12 -> 0 | Z12: =X12+Y12 -> 0
A13: Production add M- 1 | U13: =SUM(E13:S13) -> 0 | X13: =U13+V13 -> 0 | Z13: =X13+Y13 -> 0
A14: Production add M- 1 | U14: =SUM(E14:S14) -> 0 | X14: =U14+V14 -> 0 | Z14: =X14+Y14 -> 0
A15: Production add M- 1 | U15: =SUM(E15:S15) -> 0 | X15: =U15+V15 -> 0 | Z15: =X15+Y15 -> 0
A16: Production add M- 1 | U16: =SUM(E16:S16) -> 0 | X16: =U16+V16 -> 0 | Z16: =X16+Y16 -> 0
... A19: Production add M- 1 | U19: =SUM(E19:S19) -> 0 | X19: =U19+V19 -> 0 | Z19: =X19+Y19 -> 0
A20: Production add M- 1 | U20: =SUM(E20:S20) -> 0 | X20: =U20+V20 -> 0 | Z20: =X20+Y20 -> 0 | AA20: Big Chair | AB20: Small Chair | AC20: Total Pro
A21: Production add M- 1 | U21: =SUM(E21:S21) -> 0 | X21: =U21+V21 -> 0 | Z21: =X21+Y21 -> 0 | AA21: Big Chair | AB21: Small Chair | AC21: Total Pro
A22: Production add M- 1 | U22: =SUM(E22:S22) -> 0 | X22: =U22+V22 -> 0 | Z22: =X22+Y22 -> 0 | AA22: Big Chair | AB22: Small Chair | AC22: Total Pro
A23: Production add M- 1 | U23: =SUM(E23:S23) -> 0 | X23: =U23+V23 -> 0 | Z23: =X23+Y23 -> 0 | AA23: Big Chair | AB23: Small Chair | AC23: Total Pro
A24: Production add M- 1 | U24: =SUM(E24:S24) -> 0 | X24: =U24+V24 -> 0 | Z24: =X24+Y24 -> 0 | AA24: Big Chair | AB24: Small Chair | AC24: Total Pro
A25: Production add M- 1 | U25: =SUM(E25:S25) -> 0 | X25: =U25+V25 -> 0 | Z25: =X25+Y25 -> 0 | AA25: Big Chair | AB25: Small Chair | AC25: Total Pro
A26: Production add M- 1 | U26: =SUM(E26:S26) -> 0 | X26: =U26+V26 -> 0 | Z26: =X26+Y26 -> 0 | AA26: Big Chair | AB26: Small Chair | AC26: Total Pro
A27: Production Machine - 1 | E27: =SUM(E5:E26) -> 0 | F27: =SUM(F5:F26) -> 0 | G27: =SUM(G5:G26) -> 0 | H27: =SUM(H5:H26) -> 0 | I27: =SUM(I5:I26) -> 0 | J27: =SUM(J5:J26) -> 0 | K27: =SUM(K5:K26) -> 0 | L27: =SUM(L5:L26) -> 0 | ... S27: =SUM(S5:S26) -> 0 | U27: =SUM(U5:U26) -> 0 | V27: =SUM(V5:V26) -> 0 | W27: =SUM(W5:W26) -> 0 | X27: =SUM(X5:X26) -> 0 | Y27: =SUM(Y5:Y26) -> 0 | Z27: =SUM(Z5:Z26) -> 0 | AA27: ='BIG CHAIR'!CL36 -> 0 | AB27: ='Jordan Chair'!AH38 -> 627 | AC27: =X27+AA27+AB27 -> 627
A29: Production M-2 | B29: Name | C29: B.No. | D29: Date | E29: S-W | F29: Coloured | G29: Red | H29: P-Pink | I29: Gold | J29: Orange | K29: P-White | L29: Silver.B | M29: P.Silver | N29: A.Gold | O29: P.Green | P29: M.Bz | Q29: Black | R29: R-W | S29: Brown | U29: Fresh | V29: C-Mix | X29: Total | Y29: G.Rejn | Z29: G.Total
A30: Production add M- 2 | U30: =SUM(E30:S30) -> 0 | X30: =U30+V30 -> 0 | Z30: =X30+Y30 -> 0
A31: Production add M- 2 | U31: =SUM(E31:S31) -> 0 | X31: =U31+V31 -> 0 | Z31: =X31+Y31 -> 0
A32: Production add M- 2 | U32: =SUM(E32:S32) -> 0 | X32: =U32+V32 -> 0 | Z32: =X32+Y32 -> 0
A33: Production add M- 2 | U33: =SUM(E33:S33) -> 0 | X33: =U33+V33 -> 0 | Z33: =X33+Y33 -> 0
A34: Production add M- 2 | U34: =SUM(E34:S34) -> 0 | X34: =U34+V34 -> 0 | Z34: =X34+Y34 -> 0
A35: Production add M- 2 | U35: =SUM(E35:S35) -> 0 | X35: =U35+V35 -> 0 | Z35: =X35+Y35 -> 0
A36: Production add M- 2 | U36: =SUM(E36:S36) -> 0 | X36: =U36+V36 -> 0 | Z36: =X36+Y36 -> 0
A37: Production add M- 2 | U37: =SUM(E37:S37) -> 0 | X37: =U37+V37 -> 0 | Z37: =X37+Y37 -> 0
A38: Production add M- 2 | U38: =SUM(E38:S38) -> 0 | X38: =U38+V38 -> 0 | Z38: =X38+Y38 -> 0
A39: Production add M- 2 | U39: =SUM(E39:S39) -> 0 | X39: =U39+V39 -> 0 | Z39: =X39+Y39 -> 0
A40: Production add M- 2 | U40: =SUM(E40:S40) -> 0 | X40: =U40+V40 -> 0 | Z40: =X40+Y40 -> 0
A41: Production add M- 2 | U41: =SUM(E41:S41) -> 0 | X41: =U41+V41 -> 0 | Z41: =X41+Y41 -> 0
... A53: Production add M- 2 | U53: =SUM(E53:S53) -> 0 | X53: =U53+V53 -> 0 | Z53: =X53+Y53 -> 0
A54: Production add M- 2 | U54: =SUM(E54:S54) -> 0 | X54: =U54+V54 -> 0 | Z54: =X54+Y54 -> 0 | AA54: Big Chair | AB54: Small Chair | AC54: Total Pro
...

Sheet XUV
A1: Finished Production of New Mould - Period on Dated | J1: 1 | K1: 4 | L1: 25
E2: 8003 ClipON | M2: 8002 (Y) | V2: 8001 (Pearl)
A3: Production M-1 | B3: Name | C3: B.No. | D3: Date | E3: Br.Blue | F3: Black Red | G3: Br.Orange | H3: Black Green | I3: Br.Green | J3: Black Blue | K3: Br.Red | L3: Black Orange | M3: S-W | N3: T.W | O3: B . Silver | P3: B.Gold/Spl | Q3: M.Bz | R3: Brown | S3: R-W | T3: A.Gold | V3: P.Green | W3: A.Gold Red/8003 | X3: P.Pink | Y3: Red | Z3: P.White | AA3: Blue F | AB3: M.Beige F | AC3: Orange | AE3: Fresh | AF3: Mix | AH3: Total | AI3: G.R.C. | AJ3: G.Total
A4: ='Tea Table'!A4 -> Opening Stock as on | I4: =22*16 -> 352 | N4: =19*16 -> 304 | O4: =35*16 -> 560 | P4: =116*16 -> 1856 | Q4: =2*16 -> 32 | R4: =159*16 -> 2544 | T4: =47*16 -> 752 | V4: =14*16 -> 224 | X4: =7*16 -> 112 | Z4: =10*16 -> 160 | AA4: =13*16 -> 208 | AC4: =10*16 -> 160 | AE4: =SUM(E4:AC4) -> 7264 | AH4: =AF4+AE4 -> 7264 | AJ4: =AH4+AI4 -> 7264
A5: Production add M- 1 | D5: 46129 | T5: =4*16 -> 64 | AE5: =SUM(E5:AC5) -> 64 | AF5: 2 | AH5: =AE5+AF5 -> 66 | AI5: 8 | AJ5: =AH5+AI5 -> 74
A6: Production add M- 1 | D6: 46130 | T6: =31*16+15*16 -> 736 | AE6: =SUM(E6:AC6) -> 736 | AF6: =3+6 -> 9 | AH6: =AE6+AF6 -> 745 | AI6: =17+20 -> 37 | AJ6: =AH6+AI6 -> 782
A7: Production add M- 1 | D7: 46131 | T7: =27*16 -> 432 | AE7: =SUM(E7:AC7) -> 432 | AF7: 8 | AH7: =AE7+AF7 -> 440 | AI7: 17 | AJ7: =AH7+AI7 -> 457
A8: Production add M- 1 | D8: 46132 | T8: =21*16 -> 336 | AE8: =SUM(E8:AC8) -> 336 | AF8: 2 | AH8: =AE8+AF8 -> 338 | AI8: 19 | AJ8: =AH8+AI8 -> 357
A9: Production add M- 1 | D9: 46133 | N9: =11*16+26*16 -> 592 | T9: =13*16 -> 208 | AE9: =SUM(E9:AC9) -> 800 | AF9: =2+4 -> 6 | AH9: =AE9+AF9 -> 806 | AI9: =25+5 -> 30 | AJ9: =AH9+AI9 -> 836
A10: Production add M- 1 | D10: 46134 | N10: =3*16 -> 48 | AE10: =SUM(E10:AC10) -> 48 | AH10: =AE10+AF10 -> 48 | AI10: 3 | AJ10: =AH10+AI10 -> 51
A11: Production add M- 1 | AE11: =SUM(E11:AC11) -> 0 | AH11: =AE11+AF11 -> 0 | AJ11: =AH11+AI11 -> 0
A12: Production add M- 1 | AE12: =SUM(E12:AC12) -> 0 | AH12: =AE12+AF12 -> 0 | AJ12: =AH12+AI12 -> 0
A13: Production add M- 1 | AE13: =SUM(E13:AC13) -> 0 | AH13: =AE13+AF13 -> 0 | AJ13: =AH13+AI13 -> 0
A14: Production add M- 1 | AE14: =SUM(E14:AC14) -> 0 | AH14: =AE14+AF14 -> 0 | AJ14: =AH14+AI14 -> 0
A15: Production add M- 1 | AE15: =SUM(E15:AC15) -> 0 | AH15: =AE15+AF15 -> 0 | AJ15: =AH15+AI15 -> 0
A16: Production add M- 1 | AE16: =SUM(E16:AC16) -> 0 | AH16: =AE16+AF16 -> 0 | AJ16: =AH16+AI16 -> 0
A17: Production add M- 1 | AE17: =SUM(E17:AC17) -> 0 | AH17: =AE17+AF17 -> 0 | AJ17: =AH17+AI17 -> 0
A18: Production add M- 1 | AE18: =SUM(E18:AC18) -> 0 | AH18: =AE18+AF18 -> 0 | AJ18: =AH18+AI18 -> 0
A19: Production add M- 1 | AE19: =SUM(E19:AC19) -> 0 | AH19: =AE19+AF19 -> 0 | AJ19: =AH19+AI19 -> 0
A20: Production add M- 1 | AE20: =SUM(E20:AC20) -> 0 | AH20: =AE20+AF20 -> 0 | AJ20: =AH20+AI20 -> 0
A21: Production add M- 1 | AE21: =SUM(E21:AC21) -> 0 | AH21: =AE21+AF21 -> 0 | AJ21: =AH21+AI21 -> 0
A22: Production add M- 1 | AE22: =SUM(E22:AC22) -> 0 | AH22: =AE22+AF22 -> 0 | AJ22: =AH22+AI22 -> 0
... A37: Production add M- 1 | AE37: =SUM(E37:AC37) -> 0 | AH37: =AE37+AF37 -> 0 | AJ37: =AH37+AI37 -> 0
A38: Production add M- 1 | AE38: =SUM(E38:AC38) -> 0 | AH38: =AE38+AF38 -> 0 | AJ38: =AH38+AI38 -> 0 | AK38: Big Chair | AL38: Table | AM38: Total Pro
A39: Production Machine - 1 | E39: =SUM(E5:E38) -> 0 | F39: =SUM(F5:F38) -> 0 | G39: =SUM(G5:G38) -> 0 | H39: =SUM(H5:H38) -> 0 | I39: =SUM(I5:I38) -> 0 | J39: =SUM(J5:J38) -> 0 | K39: =SUM(K5:K38) -> 0 | L39: =SUM(L5:L38) -> 0 | ... AJ39: =SUM(AJ5:AJ38) -> 2557 | AK39: ='BIG CHAIR'!CL36 -> 0 | AL39: ='Tea Table'!X29 -> 0 | AM39: =AH39+AK39+AL39 -> 2443
A41: Production M-2 | B41: Name | C41: B.No. | D41: Date | E41: Br.Blue | F41: Black Red | G41: Br.Orange | H41: Black Green | I41: Br.Green | J41: Black Blue | K41: Br.Red | L41: Black Orange | M41: S-W | N41: T.W | O41: Silver | P41: B.Gold | Q41: M.Bz | R41: Brown | S41: R-W | T41: A.Gold | V41: P.Green | W41: A.Gold Red/8003 | X41: P.Pink | Y41: Red | Z41: P.White | AA41: Blue F | AB41: M.Beige F | AC41: Orange | AE41: Fresh | AF41: Mix | AH41: Total | AI41: G.R.C. | AJ41: G.Total
A42: Production add M- 2 | AE42: =SUM(E42:AC42) -> 0 | AH42: =AE42+AF42 -> 0 | AJ42: =AH42+AI42 -> 0
A43: Production add M- 2 | AE43: =SUM(E43:AC43) -> 0 | AH43: =AE43+AF43 -> 0 | AJ43: =AH43+AI43 -> 0
A44: Production add M- 2 | AE44: =SUM(E44:AC44) -> 0 | AH44: =AE44+AF44 -> 0 | AJ44: =AH44+AI44 -> 0
A45: Production add M- 2 | AE45: =SUM(E45:AC45) -> 0 | AH45: =AE45+AF45 -> 0 | AJ45: =AH45+AI45 -> 0
A46: Production add M- 2 | AE46: =SUM(E46:AC46) -> 0 | AH46: =AE46+AF46 -> 0 | AJ46: =AH46+AI46 -> 0
A47: Production add M- 2 | AE47: =SUM(E47:AC47) -> 0 | AH47: =AE47+AF47 -> 0 | AJ47: =AH47+AI47 -> 0
A48: Production add M- 2 | AE48: =SUM(E48:AC48) -> 0 | AH48: =AE48+AF48 -> 0 | AJ48: =AH48+AI48 -> 0
A49: Production add M- 2 | AE49: =SUM(E49:AC49) -> 0 | AH49: =AE49+AF49 -> 0 | AJ49: =AH49+AI49 -> 0
A50: Production add M- 2 | AE50: =SUM(E50:AC50) -> 0 | AH50: =AE50+AF50 -> 0 | AJ50: =AH50+AI50 -> 0
A51: Production add M- 2 | AE51: =SUM(E51:AC51) -> 0 | AH51: =AE51+AF51 -> 0 | AJ51: =AH51+AI51 -> 0
A52: Production add M- 2 | AE52: =SUM(E52:AC52) -> 0 | AH52: =AE52+AF52 -> 0 | AJ52: =AH52+AI52 -> 0
A53: Production add M- 2 | AE53: =SUM(E53:AC53) -> 0 | AH53: =AE53+AF53 -> 0 | AJ53: =AH53+AI53 -> 0
... A62: Production add M- 2 | AE62: =SUM(E62:AC62) -> 0 | AH62: =AE62+AF62 -> 0 | AJ62: =AH62+AI62 -> 0
A63: Production add M- 2 | AE63: =SUM(E63:AC63) -> 0 | AH63: =AE63+AF63 -> 0 | AJ63: =AH63+AI63 -> 0 | AK63: Big Chair | AL63: Table | AM63: Total Pro
...

Sheet Innova
A1: Finished Production of New Mould - Period on Dated | J1: 1 | K1: 4 | M1: 2026
E2: Innova (3001) | M2: Innova (3002) | V2: Innova(3003)
A3: Production M-1 | B3: Name | C3: B.No. | D3: Date | E3: White | G3: Orange | I3: P.Pink | J3: BROWN | K3: P.Green | M3: B.Gold | N3: Gold | O3: M.Beige | P3: S.Black | Q3: Brown | R3: R.Wood | S3: A.Gold | V3: A.Gold | W3: Brown | X3: B.Gold | Y3: M.Beige | AE3: Fresh | AF3: Mix | AH3: Total | AI3: G.R.C. | AJ3: G.Total
A4: ='Tea Table'!A4 -> Opening Stock as on | B4: Pushpanjli | AE4: =SUM(E4:AC4) -> 0 | AH4: =AF4+AE4 -> 0 | AJ4: =AH4+AI4 -> 0
A5: Production add M- 1 | AE5: =SUM(E5:AC5) -> 0 | AH5: =AE5+AF5 -> 0 | AJ5: =AH5+AI5 -> 0
A6: Production add M- 1 | AE6: =SUM(E6:AC6) -> 0 | AH6: =AE6+AF6 -> 0 | AJ6: =AH6+AI6 -> 0
A7: Production add M- 1 | AE7: =SUM(E7:AC7) -> 0 | AH7: =AE7+AF7 -> 0 | AJ7: =AH7+AI7 -> 0
A8: Production add M- 1 | AE8: =SUM(E8:AC8) -> 0 | AH8: =AE8+AF8 -> 0 | AJ8: =AH8+AI8 -> 0
A9: Production add M- 1 | AE9: =SUM(E9:AC9) -> 0 | AH9: =AE9+AF9 -> 0 | AJ9: =AH9+AI9 -> 0
A10: Production add M- 1 | AE10: =SUM(E10:AC10) -> 0 | AH10: =AE10+AF10 -> 0 | AJ10: =AH10+AI10 -> 0
A11: Production add M- 1 | AE11: =SUM(E11:AC11) -> 0 | AH11: =AE11+AF11 -> 0 | AJ11: =AH11+AI11 -> 0
A12: Production add M- 1 | AE12: =SUM(E12:AC12) -> 0 | AH12: =AE12+AF12 -> 0 | AJ12: =AH12+AI12 -> 0
A13: Production add M- 1 | AE13: =SUM(E13:AC13) -> 0 | AH13: =AE13+AF13 -> 0 | AJ13: =AH13+AI13 -> 0
A14: Production add M- 1 | AE14: =SUM(E14:AC14) -> 0 | AH14: =AE14+AF14 -> 0 | AJ14: =AH14+AI14 -> 0
A15: Production add M- 1 | AE15: =SUM(E15:AC15) -> 0 | AH15: =AE15+AF15 -> 0 | AJ15: =AH15+AI15 -> 0
A16: Production add M- 1 | AE16: =SUM(E16:AC16) -> 0 | AH16: =AE16+AF16 -> 0 | AJ16: =AH16+AI16 -> 0
... A37: Production add M- 1 | AE37: =SUM(E37:AC37) -> 0 | AH37: =AE37+AF37 -> 0 | AJ37: =AH37+AI37 -> 0
A38: Production add M- 1 | AE38: =SUM(E38:AC38) -> 0 | AH38: =AE38+AF38 -> 0 | AJ38: =AH38+AI38 -> 0 | AK38: Big Chair | AL38: Table | AM38: Total Pro
A39: Production Machine - 1 | E39: =SUM(E5:E38) -> 0 | F39: =SUM(F5:F38) -> 0 | G39: =SUM(G5:G38) -> 0 | H39: =SUM(H5:H38) -> 0 | I39: =SUM(I5:I38) -> 0 | J39: =SUM(J5:J38) -> 0 | K39: =SUM(K5:K38) -> 0 | L39: =SUM(L5:L38) -> 0 | ... N39: =SUM(N5:N38) -> 0 | O39: =SUM(O15:O38) -> 0 | P39: =SUM(P15:P38) -> 0 | Q39: =SUM(Q15:Q38) -> 0 | R39: =SUM(R15:R38) -> 0 | S39: =SUM(S5:S38) -> 0 | T39: =SUM(T15:T38) -> 0 | U39: =SUM(U5:U38) -> 0 | V39: =SUM(V5:V38) -> 0 | W39: =SUM(W5:W38) -> 0 | X39: =SUM(X5:X38) -> 0 | Y39: =SUM(Y5:Y38) -> 0 | Z39: =SUM(Z5:Z38) -> 0 | AA39: =SUM(AA5:AA38) -> 0 | AB39: =SUM(AB5:AB38) -> 0 | ... AD39: =SUM(AD5:AD38) -> 0 | AE39: =SUM(AE15:AE38) -> 0 | AF39: =SUM(AF5:AF38) -> 0 | AG39: =SUM(AG5:AG38) -> 0 | AH39: =SUM(AH15:AH38) -> 0 | AI39: =SUM(AI15:AI38) -> 0 | AJ39: =SUM(AJ15:AJ38) -> 0 | AK39: ='BIG CHAIR'!CL36 -> 0 | AL39: ='Tea Table'!X29 -> 0 | AM39: =AH39+AK39+AL39 -> 0
A41: Production M-2 | B41: Name | C41: B.No. | D41: Date | E41: White | G41: Orange | I41: P.Pink | K41: P.Green | M41: B.Gold | N41: Gold | O41: M.Beige | P41: S.Black | Q41: Brown | R41: R.Wood | S41: A.Gold | V41: A.Gold | W41: Brown | X41: B.Gold | Y41: M.Beige | AE41: Fresh | AF41: Mix | AH41: Total | AI41: G.R.C. | AJ41: G.Total
A42: Production add M- 2 | AE42: =SUM(E42:AC42) -> 0 | AH42: =AE42+AF42 -> 0 | AJ42: =AH42+AI42 -> 0
A43: Production add M- 2 | AE43: =SUM(E43:AC43) -> 0 | AH43: =AE43+AF43 -> 0 | AJ43: =AH43+AI43 -> 0
A44: Production add M- 2 | AE44: =SUM(E44:AC44) -> 0 | AH44: =AE44+AF44 -> 0 | AJ44: =AH44+AI44 -> 0
A45: Production add M- 2 | AE45: =SUM(E45:AC45) -> 0 | AH45: =AE45+AF45 -> 0 | AJ45: =AH45+AI45 -> 0
A46: Production add M- 2 | AE46: =SUM(E46:AC46) -> 0 | AH46: =AE46+AF46 -> 0 | AJ46: =AH46+AI46 -> 0
A47: Production add M- 2 | AE47: =SUM(E47:AC47) -> 0 | AH47: =AE47+AF47 -> 0 | AJ47: =AH47+AI47 -> 0
A48: Production add M- 2 | AE48: =SUM(E48:AC48) -> 0 | AH48: =AE48+AF48 -> 0 | AJ48: =AH48+AI48 -> 0
A49: Production add M- 2 | AE49: =SUM(E49:AC49) -> 0 | AH49: =AE49+AF49 -> 0 | AJ49: =AH49+AI49 -> 0
A50: Production add M- 2 | AE50: =SUM(E50:AC50) -> 0 | AH50: =AE50+AF50 -> 0 | AJ50: =AH50+AI50 -> 0
A51: Production add M- 2 | AE51: =SUM(E51:AC51) -> 0 | AH51: =AE51+AF51 -> 0 | AJ51: =AH51+AI51 -> 0
A52: Production add M- 2 | AE52: =SUM(E52:AC52) -> 0 | AH52: =AE52+AF52 -> 0 | AJ52: =AH52+AI52 -> 0
A53: Production add M- 2 | AE53: =SUM(E53:AC53) -> 0 | AH53: =AE53+AF53 -> 0 | AJ53: =AH53+AI53 -> 0
... A62: Production add M- 2 | AE62: =SUM(E62:AC62) -> 0 | AH62: =AE62+AF62 -> 0 | AJ62: =AH62+AI62 -> 0
A63: Production add M- 2 | AE63: =SUM(E63:AC63) -> 0 | AH63: =AE63+AF63 -> 0 | AJ63: =AH63+AI63 -> 0 | AK63: Big Chair | AL63: Table | AM63: Total Pro
A64: Production Machine - 2 | E64: =SUM(E42:E63) -> 0 | F64: =SUM(F42:F63) -> 0 | G64: =SUM(G42:G63) -> 0 | H64: =SUM(H42:H63) -> 0 | I64: =SUM(I42:I63) -> 0 | J64: =SUM(J42:J63) -> 0 | K64: =SUM(K42:K63) -> 0 | M64: =SUM(M42:M63) -> 0 | N64: =SUM(N42:N63) -> 0 | O64: =SUM(O42:O63) -> 0 | P64: =SUM(P42:P63) -> 0 | Q64: =SUM(Q42:Q63) -> 0 | R64: =SUM(R42:R63) -> 0 | S64: =SUM(S42:S63) -> 0 | T64: =SUM(T42:T63) -> 0 | V64: =SUM(V42:V63) -> 0 | W64: =SUM(W42:W63) -> 0 | X64: =SUM(X42:X63) -> 0 | Y64: =SUM(Y42:Y63) -> 0 | Z64: =SUM(Z42:Z63) -> 0 | AA64: =SUM(AA42:AA63) -> 0 | AB64: =SUM(AB42:AB63) -> 0 | AC64: =SUM(AC42:AC63) -> 0 | AE64: =SUM(AE42:AE63) -> 0 | AF64: =SUM(AF42:AF63) -> 0 | AG64: =SUM(AG42:AG63) -> 0 | AH64: =SUM(AH42:AH63) -> 0 | AI64: =SUM(AI42:AI63) -> 0 | AJ64: =SUM(AJ42:AJ63) -> 0 | AK64: ='BIG CHAIR'!CL77 -> 14560 | AL64: ='Tea Table'!X85 -> 0 | AM64: =AH64+AK64+AL64 -> 14560
A66: Production M-3 | B66: Name | C66: B.No. | D66: Date | E66: White | G66: Orange | I66: P.Pink | K66: P.Green | M66: B.Gold | N66: Gold | O66: M.Beige | P66: S.Black | Q66: Brown | R66: R.Wood | S66: A.Gold | V66: A.Gold | W66: Brown | X66: B.Gold | Y66: M.Beige | AE66: Fresh | AF66: Mix | AH66: Total | AI66: G.R.C. | AJ66: G.Total
A67: Production add M- 3 | AE67: =SUM(E67:AC67) -> 0 | AH67: =AE67+AF67 -> 0 | AJ67: =AH67+AI67 -> 0
A68: Production add M- 3 | AE68: =SUM(E68:AC68) -> 0 | AH68: =AE68+AF68 -> 0 | AJ68: =AH68+AI68 -> 0
A69: Production add M- 3 | AE69: =SUM(E69:AC69) -> 0 | AH69: =AE69+AF69 -> 0 | AJ69: =AH69+AI69 -> 0
A70: Production add M- 3 | AE70: =SUM(E70:AC70) -> 0 | AH70: =AE70+AF70 -> 0 | AJ70: =AH70+AI70 -> 0
...

Sheet Garden Table
A1: Finished Production of Table - Period on Dated | O1: 1 | P1: 4 | Q1: 2026
E2: Garden Table
A3: Production M-1 | B3: Name | C3: B.No. | D3: Date | E3: S-W | F3: P.Blue | G3: Red First | H3: P-Pink | I3: Gold | J3: Orange | K3: P-White | L3: Silver.B | M3: Black.Gold | N3: A.Gold | O3: P.Green | P3: T.Wood/M.B | Q3: Black | R3: R-W | S3: Brown | T3: Yellow | V3: Fresh | W3: C-Mix | Y3: Total | Z3: G.Rejn | AA3: G.Total
A4: Opening Stock as on | B4: Pushpanjli | F4: =12*12 -> 144 | H4: =17*12 -> 204 | J4: =5*12 -> 60 | K4: =23*12 -> 276 | L4: =2*12 -> 24 | M4: =101*12 -> 1212 | N4: =10*12 -> 120 | O4: =18*12 -> 216 | P4: =43*12 -> 516 | R4: =1*12 -> 12 | S4: =53*12 -> 636 | V4: =SUM(E4:T4) -> 3420 | Y4: =V4+W4 -> 3420 | AA4: =Y4+Z4 -> 3420
A5: Production add M- 1 | D5: 46126 | S5: =13*12+40*12 -> 636 | V5: =SUM(E5:T5) -> 636 | W5: 3 | Y5: =V5+W5 -> 639 | Z5: =34+10 -> 44 | AA5: =Y5+Z5 -> 683
A6: Production add M- 1 | D6: 46127 | N6: =18*12+38*12 -> 672 | S6: =11*12 -> 132 | V6: =SUM(E6:T6) -> 804 | W6: =17+5 -> 22 | Y6: =V6+W6 -> 826 | AA6: =Y6+Z6 -> 826
A7: Production add M- 1 | D7: 46128 | N7: =7*12 -> 84 | V7: =SUM(E7:T7) -> 84 | Y7: =V7+W7 -> 84 | AA7: =Y7+Z7 -> 84
A8: Production add M- 1 | V8: =SUM(E8:T8) -> 0 | Y8: =V8+W8 -> 0 | AA8: =Y8+Z8 -> 0
A9: Production add M- 1 | V9: =SUM(E9:T9) -> 0 | Y9: =V9+W9 -> 0 | AA9: =Y9+Z9 -> 0
A10: Production add M- 1 | V10: =SUM(E10:T10) -> 0 | Y10: =V10+W10 -> 0 | AA10: =Y10+Z10 -> 0
A11: Production add M- 1 | V11: =SUM(E11:T11) -> 0 | Y11: =V11+W11 -> 0 | AA11: =Y11+Z11 -> 0
A12: Production add M- 1 | V12: =SUM(E12:T12) -> 0 | Y12: =V12+W12 -> 0 | AA12: =Y12+Z12 -> 0
A13: Production add M- 1 | V13: =SUM(E13:T13) -> 0 | Y13: =V13+W13 -> 0 | AA13: =Y13+Z13 -> 0
A14: Production add M- 1 | V14: =SUM(E14:T14) -> 0 | Y14: =V14+W14 -> 0 | AA14: =Y14+Z14 -> 0
A15: Production add M- 1 | V15: =SUM(E15:T15) -> 0 | Y15: =V15+W15 -> 0 | AA15: =Y15+Z15 -> 0
A16: Production add M- 1 | V16: =SUM(E16:T16) -> 0 | Y16: =V16+W16 -> 0 | AA16: =Y16+Z16 -> 0
A17: Production add M- 1 | V17: =SUM(E17:T17) -> 0 | Y17: =V17+W17 -> 0 | AA17: =Y17+Z17 -> 0
A18: Production add M- 1 | V18: =SUM(E18:T18) -> 0 | Y18: =V18+W18 -> 0 | AA18: =Y18+Z18 -> 0
A19: Production add M- 1 | V19: =SUM(E19:T19) -> 0 | Y19: =V19+W19 -> 0 | AA19: =Y19+Z19 -> 0
A20: Production add M- 1 | V20: =SUM(E20:T20) -> 0 | Y20: =V20+W20 -> 0 | AA20: =Y20+Z20 -> 0 | AB20: Big Chair | AC20: Small Chair | AD20: Total Pro
A21: Production add M- 1 | V21: =SUM(E21:T21) -> 0 | Y21: =V21+W21 -> 0 | AA21: =Y21+Z21 -> 0 | AB21: Big Chair | AC21: Small Chair | AD21: Total Pro
A22: Production add M- 1 | V22: =SUM(E22:T22) -> 0 | Y22: =V22+W22 -> 0 | AA22: =Y22+Z22 -> 0 | AB22: Big Chair | AC22: Small Chair | AD22: Total Pro
A23: Production add M- 1 | V23: =SUM(E23:T23) -> 0 | Y23: =V23+W23 -> 0 | AA23: =Y23+Z23 -> 0 | AB23: Big Chair | AC23: Small Chair | AD23: Total Pro
A24: Production add M- 1 | V24: =SUM(E24:T24) -> 0 | Y24: =V24+W24 -> 0 | AA24: =Y24+Z24 -> 0 | AB24: Big Chair | AC24: Small Chair | AD24: Total Pro
A25: Production add M- 1 | V25: =SUM(E25:T25) -> 0 | Y25: =V25+W25 -> 0 | AA25: =Y25+Z25 -> 0 | AB25: Big Chair | AC25: Small Chair | AD25: Total Pro
A26: Production add M- 1 | V26: =SUM(E26:T26) -> 0 | Y26: =V26+W26 -> 0 | AA26: =Y26+Z26 -> 0 | AB26: Big Chair | AC26: Small Chair | AD26: Total Pro
A27: Production add M- 1 | V27: =SUM(E27:T27) -> 0 | Y27: =V27+W27 -> 0 | AA27: =Y27+Z27 -> 0 | AB27: Big Chair | AC27: Small Chair | AD27: Total Pro
A28: Production add M- 1 | V28: =SUM(E28:T28) -> 0 | Y28: =V28+W28 -> 0 | AA28: =Y28+Z28 -> 0 | AB28: Big Chair | AC28: Small Chair | AD28: Total Pro
A29: Production Machine - 1 | E29: =SUM(E5:E28) -> 0 | F29: =SUM(F5:F28) -> 0 | G29: =SUM(G5:G28) -> 0 | H29: =SUM(H5:H28) -> 0 | I29: =SUM(I5:I28) -> 0 | J29: =SUM(J5:J28) -> 0 | K29: =SUM(K5:K28) -> 0 | L29: =SUM(L5:L28) -> 0 | ... T29: =SUM(T5:T28) -> 0 | V29: =SUM(V5:V28) -> 1524 | W29: =SUM(W5:W28) -> 25 | X29: =SUM(X5:X28) -> 0 | Y29: =SUM(Y5:Y28) -> 1549 | Z29: =SUM(Z5:Z28) -> 44 | AA29: =SUM(AA5:AA28) -> 1593 | AB29: ='BIG CHAIR'!CL36 -> 0 | AC29: ='Jordan Chair'!AH38 -> 627 | AD29: =Y29+AB29+AC29 -> 2176
A31: Production M-2 | B31: Name | C31: B.No. | D31: Date | E31: S-W | F31: P.Blue | G31: Red First | H31: P-Pink | I31: Gold | J31: Orange | K31: P-White | L31: Silver.B | M31: Black.Gold | N31: A.Gold | O31: P.Green | P31: T.Wood/M.B | Q31: Black | R31: R-W | S31: Brown | T31: Yellow | V31: Fresh | W31: C-Mix | Y31: Total | Z31: G.Rejn | AA31: G.Total
A32: Production add M- 2 | V32: =SUM(E32:T32) -> 0 | Y32: =V32+W32 -> 0 | AA32: =Y32+Z32 -> 0
A33: Production add M- 2 | V33: =SUM(E33:T33) -> 0 | Y33: =V33+W33 -> 0 | AA33: =Y33+Z33 -> 0
A34: Production add M- 2 | V34: =SUM(E34:T34) -> 0 | Y34: =V34+W34 -> 0 | AA34: =Y34+Z34 -> 0
A35: Production add M- 2 | V35: =SUM(E35:T35) -> 0 | Y35: =V35+W35 -> 0 | AA35: =Y35+Z35 -> 0
A36: Production add M- 2 | V36: =SUM(E36:T36) -> 0 | Y36: =V36+W36 -> 0 | AA36: =Y36+Z36 -> 0
